<?xml version="1.0" ?>
<!-- =================================================================================== -->
<!-- |    This document was autogenerated by xacro from aero.urdf.xacro                | -->
<!-- |    EDITING THIS FILE BY HAND IS NOT RECOMMENDED                                 | -->
<!-- =================================================================================== -->
<robot name="AeroTypeFCESy" xmlns:body="http://playerstage.sourceforge.net/gazebo/xmlschema/#body" xmlns:controller="http://playerstage.sourceforge.net/gazebo/xmlschema/#controller" xmlns:gazebo="http://playerstage.sourceforge.net/gazebo/xmlschema/#gz" xmlns:geom="http://playerstage.sourceforge.net/gazebo/xmlschema/#geom" xmlns:interface="http://playerstage.sourceforge.net/gazebo/xmlschema/#interface" xmlns:joint="http://playerstage.sourceforge.net/gazebo/xmlschema/#joint" xmlns:model="http://playerstage.sourceforge.net/gazebo/xmlschema/#model" xmlns:physics="http://playerstage.sourceforge.net/gazebo/xmlschema/#physics" xmlns:renderable="http://playerstage.sourceforge.net/gazebo/xmlschema/#renderable" xmlns:rendering="http://playerstage.sourceforge.net/gazebo/xmlschema/#rendering" xmlns:sensor="http://playerstage.sourceforge.net/gazebo/xmlschema/#sensor" xmlns:xacro="http://playerstage.sourceforge.net/gazebo/xmlschema/#interface" xmlns:xi="http://www.w3.org/2001/XInclude">
  <!-- ============================   aero(typeF_upper)   ============================ -->
  <link name="waist_link">
    <visual>
      <origin rpy="0 -0 0" xyz="0 0 0"/>
      <geometry>
        <mesh filename="package://aero_description/meshes/typeF_upperbody/WAIST_LINK0_mesh.dae" scale="1 1 1"/>
      </geometry>
    </visual>
    <collision>
      <origin rpy="0 -0 0" xyz="0 0 0"/>
      <geometry>
        <mesh filename="package://aero_description/meshes/typeF_upperbody/WAIST_LINK0_mesh.dae" scale="1 1 1"/>
      </geometry>
    </collision>
    <inertial>
      <mass value="1.257"/>
      <origin rpy="0 -0 0" xyz="0 0 0.0"/>
      <inertia ixx="0.034" ixy="0" ixz="0" iyy="0.034" iyz="0" izz="0.018"/>
    </inertial>
  </link>
  <gazebo reference="waist_link">
    <mu1>0.9</mu1>
    <mu2>0.9</mu2>
  </gazebo>
  <link name="hip_sphere_link">
    <visual>
      <origin rpy="0 -0 0" xyz="0 0 0"/>
      <geometry>
        <mesh filename="package://aero_description/meshes/typeF_upperbody/WAIST_LINK1_mesh.dae" scale="1 1 1"/>
      </geometry>
    </visual>
    <collision>
      <origin rpy="0 -0 0" xyz="0 0 0"/>
      <geometry>
        <mesh filename="package://aero_description/meshes/typeF_upperbody/WAIST_LINK1_mesh.dae" scale="1 1 1"/>
      </geometry>
    </collision>
    <inertial>
      <mass value="1.257"/>
      <origin rpy="0 -0 0" xyz="0 0 0.042"/>
      <!-- inertia ixx="0.034" ixy="0" ixz="0" iyy="0.034" iyz="0" izz="0.018"/ -->
      <!-- just fixed for gazebo / reduce inertia-->
      <inertia ixx="0.01" ixy="0" ixz="0" iyy="0.01" iyz="0" izz="0.007"/>
    </inertial>
  </link>
  <gazebo reference="hip_sphere_link">
    <mu1>0.9</mu1>
    <mu2>0.9</mu2>
  </gazebo>
  <link name="hip_center">
    <inertial>
      <mass value="0.1"/>
      <origin rpy="0 -0 0" xyz="0 0 0"/>
      <!--inertia ixx="0.01" ixy="0" ixz="0" iyy="0.01" iyz="0" izz="0.01"/-->
      <!-- just fixed for gazebo / reduce inertia-->
      <inertia ixx="0.003" ixy="0" ixz="0" iyy="0.003" iyz="0" izz="0.003"/>
    </inertial>
  </link>
  <gazebo reference="hip_center">
    <mu1>0.9</mu1>
    <mu2>0.9</mu2>
  </gazebo>
  <link name="body_link">
    <visual>
      <origin rpy="0 -0 0" xyz="0 0 0"/>
      <geometry>
        <mesh filename="package://aero_description/meshes/typeF_upperbody/WAIST_LINK3_mesh.dae" scale="1 1 1"/>
      </geometry>
    </visual>
    <collision>
      <origin rpy="0 -0 0" xyz="0 0 0"/>
      <geometry>
        <mesh filename="package://aero_description/meshes/typeF_upperbody/WAIST_LINK3_mesh.dae" scale="1 1 1"/>
      </geometry>
    </collision>
    <inertial>
      <mass value="10.551"/>
      <origin rpy="0 -0 0" xyz="0 0 0.22"/>
      <inertia ixx="0.13" ixy="0" ixz="0" iyy="0.12" iyz="0" izz="0.114"/>
    </inertial>
  </link>
  <gazebo reference="body_link">
    <mu1>0.9</mu1>
    <mu2>0.9</mu2>
  </gazebo>
  <link name="l_shoulder_link">
    <visual>
      <origin rpy="-0.174532925 -0 0" xyz="0 0 0"/>
      <geometry>
        <mesh filename="package://aero_description/meshes/typeF_upperbody/LARM_LINK1_mesh.dae" scale="1 1 1"/>
      </geometry>
    </visual>
    <collision>
      <origin rpy="-0.174532925 -0 0" xyz="0 0 0"/>
      <geometry>
        <mesh filename="package://aero_description/meshes/typeF_upperbody/LARM_LINK1_mesh.dae" scale="1 1 1"/>
      </geometry>
    </collision>
    <inertial>
      <mass value="0.242"/>
      <!--origin xyz="0 0.02 0" rpy="0 -0 0"/>
      <inertia ixx="0.000228" ixy="0" ixz="0" iyy="0.000148" iyz="0" izz="0.000263"/-->
      <!-- just fixed for gazebo / increase inertia-->
      <origin rpy="0 -0 0" xyz="0 0.02 0.015"/>
      <inertia ixx="0.00133" ixy="0" ixz="0" iyy="0.001" iyz="0" izz="0.00133"/>
    </inertial>
  </link>
  <gazebo reference="l_shoulder_link">
    <mu1>0.9</mu1>
    <mu2>0.9</mu2>
  </gazebo>
  <link name="l_shoulder_center">
    <visual>
      <origin rpy="0 -0 0" xyz="0 0 0"/>
      <geometry>
        <mesh filename="package://aero_description/meshes/typeF_upperbody/LARM_LINK2_mesh.dae" scale="1 1 1"/>
      </geometry>
    </visual>
    <collision>
      <origin rpy="0 -0 0" xyz="0 0 0"/>
      <geometry>
        <mesh filename="package://aero_description/meshes/typeF_upperbody/LARM_LINK2_mesh.dae" scale="1 1 1"/>
      </geometry>
    </collision>
    <inertial>
      <mass value="0.744"/>
      <!--origin xyz="0 0.01 0" rpy="0 -0 0"/-->
      <origin rpy="0 -0 0" xyz="0 -0.01 -0.06"/>
      <inertia ixx="0.000841" ixy="0" ixz="0" iyy="0.000835" iyz="0" izz="0.000304"/>
    </inertial>
  </link>
  <gazebo reference="l_shoulder_center">
    <mu1>0.9</mu1>
    <mu2>0.9</mu2>
  </gazebo>
  <link name="l_upperarm_link">
    <visual>
      <origin rpy="0 -0 0" xyz="0 0 0"/>
      <geometry>
        <mesh filename="package://aero_description/meshes/typeF_upperbody/LARM_LINK3_mesh.dae" scale="1 1 1"/>
      </geometry>
    </visual>
    <collision>
      <origin rpy="0 -0 0" xyz="0 0 0"/>
      <geometry>
        <mesh filename="package://aero_description/meshes/typeF_upperbody/LARM_LINK3_mesh.dae" scale="1 1 1"/>
      </geometry>
    </collision>
    <inertial>
      <mass value="0.574"/>
      <!--origin xyz="0.005 0 -0.0654" rpy="0 -0 0"/>
      <inertia ixx="0.00114" ixy="0" ixz="0" iyy="0.00117" iyz="0" izz="0.000269"/-->
      <!-- fix for gazebo -->
      <origin rpy="0 -0 0" xyz="0.005 0 -0.0654"/>
      <inertia ixx="0.00214" ixy="0" ixz="0" iyy="0.00217" iyz="0" izz="0.003"/>
    </inertial>
  </link>
  <gazebo reference="l_upperarm_link">
    <mu1>0.9</mu1>
    <mu2>0.9</mu2>
  </gazebo>
  <link name="l_elbow_link">
    <visual>
      <origin rpy="0 -0 0" xyz="-0.035 0 -0.035"/>
      <geometry>
        <mesh filename="package://aero_description/meshes/typeF_upperbody/LARM_LINK4_mesh.dae" scale="1 1 1"/>
      </geometry>
    </visual>
    <collision>
      <origin rpy="0 -0 0" xyz="-0.035 0 -0.035"/>
      <geometry>
        <mesh filename="package://aero_description/meshes/typeF_upperbody/LARM_LINK4_mesh.dae" scale="1 1 1"/>
      </geometry>
    </collision>
    <inertial>
      <mass value="0.711"/>
      <!--origin xyz="0.0047 0 -0.0546" rpy="0 -0 0"/>
      <inertia ixx="0.00178" ixy="0" ixz="0" iyy="0.00179" iyz="0" izz="0.000273"/-->
      <!-- fix for gazebo -->
      <origin rpy="0 -0 0" xyz="-0.03 0 -0.0546"/>
      <inertia ixx="0.00178" ixy="0" ixz="0" iyy="0.00179" iyz="0" izz="0.0035"/>
    </inertial>
  </link>
  <gazebo reference="l_elbow_link">
    <mu1>0.9</mu1>
    <mu2>0.9</mu2>
  </gazebo>
  <link name="l_forearm_link">
    <visual>
      <origin rpy="0 0 -1.5707963267948966" xyz="0 0 0"/>
      <geometry>
        <mesh filename="package://aero_description/meshes/typeF_upperbody/LARM_LINK5_mesh.dae" scale="1 1 1"/>
      </geometry>
    </visual>
    <collision>
      <origin rpy="0 0 -1.5707963267948966" xyz="0 0 0"/>
      <geometry>
        <mesh filename="package://aero_description/meshes/typeF_upperbody/LARM_LINK5_mesh.dae" scale="1 1 1"/>
      </geometry>
    </collision>
    <inertial>
      <mass value="0.132"/>
      <origin rpy="0 -0 0" xyz="0.006 0 -0.0738"/>
      <!--inertia ixx="0.00276" ixy="0" ixz="0" iyy="0.00286" iyz="0" izz="0.004"/-->
      <inertia ixx="0.0007" ixy="0" ixz="0" iyy="0.0007" iyz="0" izz="0.0004"/>
    </inertial>
  </link>
  <gazebo reference="l_forearm_link">
    <mu1>0.9</mu1>
    <mu2>0.9</mu2>
  </gazebo>
  <link name="l_wrist_center">
    <inertial>
      <mass value="0.05"/>
      <origin rpy="0 -0 0" xyz="0 0 0"/>
      <inertia ixx="0.0001" ixy="0" ixz="0" iyy="0.0001" iyz="0" izz="0.0001"/>
    </inertial>
  </link>
  <gazebo reference="l_wrist_center">
    <mu1>0.9</mu1>
    <mu2>0.9</mu2>
  </gazebo>
  <link name="neck_link">
    <visual>
      <origin rpy="0 -0 0" xyz="0 0 0"/>
      <geometry>
        <mesh filename="package://aero_description/meshes/typeF_upperbody/NECK_LINK1_mesh.dae" scale="1 1 1"/>
      </geometry>
    </visual>
    <collision>
      <origin rpy="0 -0 0" xyz="0 0 0"/>
      <geometry>
        <mesh filename="package://aero_description/meshes/typeF_upperbody/NECK_LINK1_mesh.dae" scale="1 1 1"/>
      </geometry>
    </collision>
    <inertial>
      <mass value="0.341"/>
      <origin rpy="0 -0 0" xyz="0 0 0.0595"/>
      <!--inertia ixx="1.64186e-35" ixy="0" ixz="0" iyy="1.64186e-35" iyz="0" izz="0"/-->
      <inertia ixx="0.001" ixy="0" ixz="0" iyy="0.001" iyz="0" izz="0.002"/>
    </inertial>
  </link>
  <gazebo reference="neck_link">
    <mu1>0.9</mu1>
    <mu2>0.9</mu2>
  </gazebo>
  <link name="head_base_link">
    <visual>
      <origin rpy="0 -0 0" xyz="0 0 0"/>
      <geometry>
        <mesh filename="package://aero_description/meshes/typeF_upperbody/NECK_LINK2_mesh.dae" scale="1 1 1"/>
      </geometry>
    </visual>
    <collision>
      <origin rpy="0 -0 0" xyz="0 0 0"/>
      <geometry>
        <mesh filename="package://aero_description/meshes/typeF_upperbody/NECK_LINK2_mesh.dae" scale="1 1 1"/>
      </geometry>
    </collision>
    <inertial>
      <mass value="0.1"/>
      <origin rpy="0 -0 0" xyz="0 0 0"/>
      <inertia ixx="0.0005" ixy="0" ixz="0" iyy="0.0005" iyz="0" izz="0.0005"/>
    </inertial>
  </link>
  <gazebo reference="head_base_link">
    <mu1>0.9</mu1>
    <mu2>0.9</mu2>
  </gazebo>
  <link name="head_link">
    <visual>
      <origin rpy="0 -0 0" xyz="0 0 0"/>
      <geometry>
        <mesh filename="package://aero_description/meshes/typeF_upperbody/NECK_LINK3_mesh.dae" scale="1 1 1"/>
      </geometry>
    </visual>
    <collision>
      <origin rpy="0 -0 0" xyz="0 0 0"/>
      <geometry>
        <mesh filename="package://aero_description/meshes/typeF_upperbody/NECK_LINK3_mesh.dae" scale="1 1 1"/>
      </geometry>
    </collision>
    <inertial>
      <mass value="0.974"/>
      <origin rpy="0 -0 0" xyz="0.01 0 0.070"/>
      <inertia ixx="0.005" ixy="0" ixz="0" iyy="0.005" iyz="0" izz="0.005"/>
    </inertial>
  </link>
  <gazebo reference="head_link">
    <mu1>0.9</mu1>
    <mu2>0.9</mu2>
  </gazebo>
  <link name="r_shoulder_link">
    <visual>
      <origin rpy="0.174532925 -0 0" xyz="0 0 0"/>
      <geometry>
        <mesh filename="package://aero_description/meshes/typeF_upperbody/RARM_LINK1_mesh.dae" scale="1 1 1"/>
      </geometry>
    </visual>
    <collision>
      <origin rpy="0.174532925 -0 0" xyz="0 0 0"/>
      <geometry>
        <mesh filename="package://aero_description/meshes/typeF_upperbody/RARM_LINK1_mesh.dae" scale="1 1 1"/>
      </geometry>
    </collision>
    <inertial>
      <mass value="0.242"/>
      <!--origin xyz="0 -0.02 0" rpy="0 -0 0"/>
      <inertia ixx="0.000228" ixy="0" ixz="0" iyy="0.000148" iyz="0" izz="0.000263"/-->
      <origin rpy="0 -0 0" xyz="0 -0.02 0.015"/>
      <inertia ixx="0.00133" ixy="0" ixz="0" iyy="0.001" iyz="0" izz="0.00133"/>
    </inertial>
  </link>
  <gazebo reference="r_shoulder_link">
    <mu1>0.9</mu1>
    <mu2>0.9</mu2>
  </gazebo>
  <link name="r_shoulder_center">
    <visual>
      <origin rpy="0 -0 0" xyz="0 0 0"/>
      <geometry>
        <mesh filename="package://aero_description/meshes/typeF_upperbody/RARM_LINK2_mesh.dae" scale="1 1 1"/>
      </geometry>
    </visual>
    <collision>
      <origin rpy="0 -0 0" xyz="0 0 0"/>
      <geometry>
        <mesh filename="package://aero_description/meshes/typeF_upperbody/RARM_LINK2_mesh.dae" scale="1 1 1"/>
      </geometry>
    </collision>
    <inertial>
      <mass value="0.744"/>
      <!--origin xyz="0 -0.01 0" rpy="0 -0 0"/-->
      <origin rpy="0 -0 0" xyz="0 0.01 -0.06"/>
      <inertia ixx="0.000841" ixy="0" ixz="0" iyy="0.000835" iyz="0" izz="0.000305"/>
    </inertial>
  </link>
  <gazebo reference="r_shoulder_center">
    <mu1>0.9</mu1>
    <mu2>0.9</mu2>
  </gazebo>
  <link name="r_upperarm_link">
    <visual>
      <origin rpy="0 -0 0" xyz="0 0 0"/>
      <geometry>
        <mesh filename="package://aero_description/meshes/typeF_upperbody/RARM_LINK3_mesh.dae" scale="1 1 1"/>
      </geometry>
    </visual>
    <collision>
      <origin rpy="0 -0 0" xyz="0 0 0"/>
      <geometry>
        <mesh filename="package://aero_description/meshes/typeF_upperbody/RARM_LINK3_mesh.dae" scale="1 1 1"/>
      </geometry>
    </collision>
    <inertial>
      <mass value="0.574"/>
      <!--origin xyz="0.005 0 -0.0654" rpy="0 -0 0"/>
      <inertia ixx="0.00114" ixy="0" ixz="0" iyy="0.00117" iyz="0" izz="0.000269"/-->
      <!-- fix for gazebo -->
      <origin rpy="0 -0 0" xyz="0.005 0 -0.0654"/>
      <inertia ixx="0.00214" ixy="0" ixz="0" iyy="0.00217" iyz="0" izz="0.003"/>
    </inertial>
  </link>
  <gazebo reference="r_upperarm_link">
    <mu1>0.9</mu1>
    <mu2>0.9</mu2>
  </gazebo>
  <link name="r_elbow_link">
    <visual>
      <origin rpy="0 -0 0" xyz="-0.035 0 -0.035"/>
      <geometry>
        <mesh filename="package://aero_description/meshes/typeF_upperbody/RARM_LINK4_mesh.dae" scale="1 1 1"/>
      </geometry>
    </visual>
    <collision>
      <origin rpy="0 -0 0" xyz="-0.035 0 -0.035"/>
      <geometry>
        <mesh filename="package://aero_description/meshes/typeF_upperbody/RARM_LINK4_mesh.dae" scale="1 1 1"/>
      </geometry>
    </collision>
    <inertial>
      <mass value="0.711"/>
      <!--origin xyz="0.0047 0 -0.0546" rpy="0 -0 0"/>
      <inertia ixx="0.00178" ixy="0" ixz="0" iyy="0.00179" iyz="0" izz="0.000273"/-->
      <!-- fix for gazebo -->
      <origin rpy="0 -0 0" xyz="-0.03 0 -0.0546"/>
      <inertia ixx="0.00178" ixy="0" ixz="0" iyy="0.00179" iyz="0" izz="0.0035"/>
    </inertial>
  </link>
  <gazebo reference="r_elbow_link">
    <mu1>0.9</mu1>
    <mu2>0.9</mu2>
  </gazebo>
  <link name="r_forearm_link">
    <visual>
      <origin rpy="0 0 1.5707963267948966" xyz="0 0 0"/>
      <geometry>
        <mesh filename="package://aero_description/meshes/typeF_upperbody/RARM_LINK5_mesh.dae" scale="1 1 1"/>
      </geometry>
    </visual>
    <collision>
      <origin rpy="0 0 1.5707963267948966" xyz="0 0 0"/>
      <geometry>
        <mesh filename="package://aero_description/meshes/typeF_upperbody/RARM_LINK5_mesh.dae" scale="1 1 1"/>
      </geometry>
    </collision>
    <inertial>
      <mass value="0.132"/>
      <origin rpy="0 -0 0" xyz="0.006 0 -0.0738"/>
      <!--inertia ixx="0.00276" ixy="0" ixz="0" iyy="0.00286" iyz="0" izz="0.004"/-->
      <inertia ixx="0.0007" ixy="0" ixz="0" iyy="0.0007" iyz="0" izz="0.0004"/>
    </inertial>
  </link>
  <gazebo reference="r_forearm_link">
    <mu1>0.9</mu1>
    <mu2>0.9</mu2>
  </gazebo>
  <link name="r_wrist_center">
    <inertial>
      <mass value="0.05"/>
      <origin rpy="0 -0 0" xyz="0 0 0"/>
      <inertia ixx="0.0001" ixy="0" ixz="0" iyy="0.0001" iyz="0" izz="0.0001"/>
    </inertial>
  </link>
  <gazebo reference="r_wrist_center">
    <mu1>0.9</mu1>
    <mu2>0.9</mu2>
  </gazebo>
  <joint name="waist_y_joint" type="revolute">
    <parent link="waist_link"/>
    <child link="hip_sphere_link"/>
    <origin rpy="0 -0 0 " xyz="0 0 0.010"/>
    <axis xyz="0 0 1"/>
    <!-- from -120 to 120 degrees-->
    <limit effort="500" lower="-2.09" upper="2.09" velocity="0.6"/>
    <dynamics damping="0.2" friction="0"/>
  </joint>
  <transmission name="waist_y_joint_trans">
    <type>transmission_interface/SimpleTransmission</type>
    <joint name="waist_y_joint">
      <!-- dupricated in kinetic -->
      <!--hardwareInterface>hardware_interface/EffortJointInterface</hardwareInterface-->
      <!--hardwareInterface>EffortJointInterface</hardwareInterface-->
      <hardwareInterface>VelocityJointInterface</hardwareInterface>
    </joint>
    <actuator name="waist_y_joint_motor">
      <!-- dupricated in kinetic -->
      <!--hardwareInterface>hardware_interface/EffortJointInterface</hardwareInterface-->
      <!--hardwareInterface>EffortJointInterface</hardwareInterface-->
      <hardwareInterface>VelocityJointInterface</hardwareInterface>
      <mechanicalReduction>1</mechanicalReduction>
    </actuator>
  </transmission>
  <gazebo reference="waist_y_joint">
    <implicitSpringDamper>0</implicitSpringDamper>
  </gazebo>
  <joint name="waist_p_joint" type="revolute">
    <parent link="hip_sphere_link"/>
    <child link="hip_center"/>
    <origin rpy="0 -0 0 " xyz="0 0 0.1355"/>
    <axis xyz="0 1 0"/>
    <!-- from -5 to 35 degrees-->
    <limit effort="2000" lower="-0.087" upper="0.61" velocity="0.5"/>
    <dynamics damping="0.2" friction="0"/>
  </joint>
  <transmission name="waist_p_joint_trans">
    <type>transmission_interface/SimpleTransmission</type>
    <joint name="waist_p_joint">
      <!-- dupricated in kinetic -->
      <!--hardwareInterface>hardware_interface/EffortJointInterface</hardwareInterface-->
      <!--hardwareInterface>EffortJointInterface</hardwareInterface-->
      <hardwareInterface>VelocityJointInterface</hardwareInterface>
    </joint>
    <actuator name="waist_p_joint_motor">
      <!-- dupricated in kinetic -->
      <!--hardwareInterface>hardware_interface/EffortJointInterface</hardwareInterface-->
      <!--hardwareInterface>EffortJointInterface</hardwareInterface-->
      <hardwareInterface>VelocityJointInterface</hardwareInterface>
      <mechanicalReduction>1</mechanicalReduction>
    </actuator>
  </transmission>
  <gazebo reference="waist_p_joint">
    <implicitSpringDamper>0</implicitSpringDamper>
  </gazebo>
  <joint name="waist_r_joint" type="revolute">
    <parent link="hip_center"/>
    <child link="body_link"/>
    <origin rpy="0 -0 0 " xyz="0 0 0"/>
    <axis xyz="1 0 0"/>
    <!-- from -1 to 1 degrees-->
    <limit effort="2000" lower="-0.017" upper="0.017" velocity="0.4"/>
    <dynamics damping="0.2" friction="0"/>
  </joint>
  <transmission name="waist_r_joint_trans">
    <type>transmission_interface/SimpleTransmission</type>
    <joint name="waist_r_joint">
      <!-- dupricated in kinetic -->
      <!--hardwareInterface>hardware_interface/EffortJointInterface</hardwareInterface-->
      <!--hardwareInterface>EffortJointInterface</hardwareInterface-->
      <hardwareInterface>VelocityJointInterface</hardwareInterface>
    </joint>
    <actuator name="waist_r_joint_motor">
      <!-- dupricated in kinetic -->
      <!--hardwareInterface>hardware_interface/EffortJointInterface</hardwareInterface-->
      <!--hardwareInterface>EffortJointInterface</hardwareInterface-->
      <hardwareInterface>VelocityJointInterface</hardwareInterface>
      <mechanicalReduction>1</mechanicalReduction>
    </actuator>
  </transmission>
  <gazebo reference="waist_r_joint">
    <implicitSpringDamper>0</implicitSpringDamper>
  </gazebo>
  <joint name="l_shoulder_p_joint" type="revolute">
    <parent link="body_link"/>
    <child link="l_shoulder_link"/>
    <origin rpy="0 -0 0 " xyz="-0.01815 0.1342 0.3049"/>
    <axis xyz="0 0.984808 -0.173648"/>
    <!-- from -88 to 15 degrees-->
    <limit effort="200" lower="-1.535" upper="0.261" velocity="0.4"/>
    <dynamics damping="0.2" friction="0"/>
  </joint>
  <transmission name="l_shoulder_p_joint_trans">
    <type>transmission_interface/SimpleTransmission</type>
    <joint name="l_shoulder_p_joint">
      <!-- dupricated in kinetic -->
      <!--hardwareInterface>hardware_interface/EffortJointInterface</hardwareInterface-->
      <!--hardwareInterface>EffortJointInterface</hardwareInterface-->
      <hardwareInterface>VelocityJointInterface</hardwareInterface>
    </joint>
    <actuator name="l_shoulder_p_joint_motor">
      <!-- dupricated in kinetic -->
      <!--hardwareInterface>hardware_interface/EffortJointInterface</hardwareInterface-->
      <!--hardwareInterface>EffortJointInterface</hardwareInterface-->
      <hardwareInterface>VelocityJointInterface</hardwareInterface>
      <mechanicalReduction>1</mechanicalReduction>
    </actuator>
  </transmission>
  <gazebo reference="l_shoulder_p_joint">
    <implicitSpringDamper>0</implicitSpringDamper>
  </gazebo>
  <joint name="l_shoulder_r_joint" type="revolute">
    <parent link="l_shoulder_link"/>
    <child link="l_shoulder_center"/>
    <origin rpy="0 -0 0 " xyz="0 0.05978 0.028046"/>
    <axis xyz="1 0 0"/>
    <!-- from 0 to 90 degrees-->
    <limit effort="100" lower="0" upper="1.5707" velocity="0.6"/>
    <dynamics damping="0.2" friction="0"/>
  </joint>
  <transmission name="l_shoulder_r_joint_trans">
    <type>transmission_interface/SimpleTransmission</type>
    <joint name="l_shoulder_r_joint">
      <!-- dupricated in kinetic -->
      <!--hardwareInterface>hardware_interface/EffortJointInterface</hardwareInterface-->
      <!--hardwareInterface>EffortJointInterface</hardwareInterface-->
      <hardwareInterface>VelocityJointInterface</hardwareInterface>
    </joint>
    <actuator name="l_shoulder_r_joint_motor">
      <!-- dupricated in kinetic -->
      <!--hardwareInterface>hardware_interface/EffortJointInterface</hardwareInterface-->
      <!--hardwareInterface>EffortJointInterface</hardwareInterface-->
      <hardwareInterface>VelocityJointInterface</hardwareInterface>
      <mechanicalReduction>1</mechanicalReduction>
    </actuator>
  </transmission>
  <gazebo reference="l_shoulder_r_joint">
    <implicitSpringDamper>0</implicitSpringDamper>
  </gazebo>
  <joint name="l_shoulder_y_joint" type="revolute">
    <parent link="l_shoulder_center"/>
    <child link="l_upperarm_link"/>
    <origin rpy="0 -0 0 " xyz="0 -0.010 -0.127"/>
    <axis xyz="0 0 1"/>
    <!-- from -180 to 45 degrees-->
    <limit effort="100" lower="-1.5707" upper="0.785398" velocity="1.2"/>
    <dynamics damping="0.2" friction="0"/>
  </joint>
  <transmission name="l_shoulder_y_joint_trans">
    <type>transmission_interface/SimpleTransmission</type>
    <joint name="l_shoulder_y_joint">
      <!-- dupricated in kinetic -->
      <!--hardwareInterface>hardware_interface/EffortJointInterface</hardwareInterface-->
      <!--hardwareInterface>EffortJointInterface</hardwareInterface-->
      <hardwareInterface>VelocityJointInterface</hardwareInterface>
    </joint>
    <actuator name="l_shoulder_y_joint_motor">
      <!-- dupricated in kinetic -->
      <!--hardwareInterface>hardware_interface/EffortJointInterface</hardwareInterface-->
      <!--hardwareInterface>EffortJointInterface</hardwareInterface-->
      <hardwareInterface>VelocityJointInterface</hardwareInterface>
      <mechanicalReduction>1</mechanicalReduction>
    </actuator>
  </transmission>
  <gazebo reference="l_shoulder_y_joint">
    <implicitSpringDamper>0</implicitSpringDamper>
  </gazebo>
  <joint name="l_elbow_joint" type="revolute">
    <parent link="l_upperarm_link"/>
    <child link="l_elbow_link"/>
    <origin rpy="0 -0 0 " xyz="0.035 0 -0.1625"/>
    <axis xyz="0 1 0"/>
    <!-- from -171 to 0 degrees-->
    <limit effort="100" lower="-3.0" upper="0" velocity="1.2"/>
    <dynamics damping="0.2" friction="0"/>
  </joint>
  <transmission name="l_elbow_joint_trans">
    <type>transmission_interface/SimpleTransmission</type>
    <joint name="l_elbow_joint">
      <!-- dupricated in kinetic -->
      <!--hardwareInterface>hardware_interface/EffortJointInterface</hardwareInterface-->
      <!--hardwareInterface>EffortJointInterface</hardwareInterface-->
      <hardwareInterface>VelocityJointInterface</hardwareInterface>
    </joint>
    <actuator name="l_elbow_joint_motor">
      <!-- dupricated in kinetic -->
      <!--hardwareInterface>hardware_interface/EffortJointInterface</hardwareInterface-->
      <!--hardwareInterface>EffortJointInterface</hardwareInterface-->
      <hardwareInterface>VelocityJointInterface</hardwareInterface>
      <mechanicalReduction>1</mechanicalReduction>
    </actuator>
  </transmission>
  <gazebo reference="l_elbow_joint">
    <implicitSpringDamper>0</implicitSpringDamper>
  </gazebo>
  <joint name="l_wrist_y_joint" type="revolute">
    <parent link="l_elbow_link"/>
    <child link="l_forearm_link"/>
    <origin rpy="0 -0 0 " xyz="-0.035 0 -0.070"/>
    <axis xyz="0 0 1"/>
    <!-- from -180 to 180 degrees-->
    <limit effort="100" lower="-1.5707" upper="1.5707" velocity="1.3"/>
    <dynamics damping="0.2" friction="0"/>
  </joint>
  <transmission name="l_wrist_y_joint_trans">
    <type>transmission_interface/SimpleTransmission</type>
    <joint name="l_wrist_y_joint">
      <!-- dupricated in kinetic -->
      <!--hardwareInterface>hardware_interface/EffortJointInterface</hardwareInterface-->
      <!--hardwareInterface>EffortJointInterface</hardwareInterface-->
      <hardwareInterface>VelocityJointInterface</hardwareInterface>
    </joint>
    <actuator name="l_wrist_y_joint_motor">
      <!-- dupricated in kinetic -->
      <!--hardwareInterface>hardware_interface/EffortJointInterface</hardwareInterface-->
      <!--hardwareInterface>EffortJointInterface</hardwareInterface-->
      <hardwareInterface>VelocityJointInterface</hardwareInterface>
      <mechanicalReduction>1</mechanicalReduction>
    </actuator>
  </transmission>
  <gazebo reference="l_wrist_y_joint">
    <implicitSpringDamper>0</implicitSpringDamper>
  </gazebo>
  <joint name="l_wrist_p_joint" type="revolute">
    <parent link="l_forearm_link"/>
    <child link="l_wrist_center"/>
    <origin rpy="0 -0 0 " xyz="0 0 -0.1955"/>
    <axis xyz="0 1 0"/>
    <!-- from -5 to 5 degrees-->
    <limit effort="100" lower="-0.087" upper="0.087" velocity="0.9"/>
    <dynamics damping="0.2" friction="0"/>
  </joint>
  <transmission name="l_wrist_p_joint_trans">
    <type>transmission_interface/SimpleTransmission</type>
    <joint name="l_wrist_p_joint">
      <!-- dupricated in kinetic -->
      <!--hardwareInterface>hardware_interface/EffortJointInterface</hardwareInterface-->
      <!--hardwareInterface>EffortJointInterface</hardwareInterface-->
      <hardwareInterface>VelocityJointInterface</hardwareInterface>
    </joint>
    <actuator name="l_wrist_p_joint_motor">
      <!-- dupricated in kinetic -->
      <!--hardwareInterface>hardware_interface/EffortJointInterface</hardwareInterface-->
      <!--hardwareInterface>EffortJointInterface</hardwareInterface-->
      <hardwareInterface>VelocityJointInterface</hardwareInterface>
      <mechanicalReduction>1</mechanicalReduction>
    </actuator>
  </transmission>
  <gazebo reference="l_wrist_p_joint">
    <implicitSpringDamper>0</implicitSpringDamper>
  </gazebo>
  <joint name="l_wrist_r_joint" type="revolute">
    <parent link="l_wrist_center"/>
    <child link="l_hand_yaw_link"/>
    <origin rpy="0 -0 0 " xyz="0 0 0"/>
    <axis xyz="1 0 0"/>
    <!-- from -85 to 25 degrees-->
    <limit effort="100" lower="-1.484" upper="0.436" velocity="2.1"/>
    <dynamics damping="0.2" friction="0"/>
  </joint>
  <transmission name="l_wrist_r_joint_trans">
    <type>transmission_interface/SimpleTransmission</type>
    <joint name="l_wrist_r_joint">
      <!-- dupricated in kinetic -->
      <!--hardwareInterface>hardware_interface/EffortJointInterface</hardwareInterface-->
      <!--hardwareInterface>EffortJointInterface</hardwareInterface-->
      <hardwareInterface>VelocityJointInterface</hardwareInterface>
    </joint>
    <actuator name="l_wrist_r_joint_motor">
      <!-- dupricated in kinetic -->
      <!--hardwareInterface>hardware_interface/EffortJointInterface</hardwareInterface-->
      <!--hardwareInterface>EffortJointInterface</hardwareInterface-->
      <hardwareInterface>VelocityJointInterface</hardwareInterface>
      <mechanicalReduction>1</mechanicalReduction>
    </actuator>
  </transmission>
  <gazebo reference="l_wrist_r_joint">
    <implicitSpringDamper>0</implicitSpringDamper>
  </gazebo>
  <joint name="neck_y_joint" type="revolute">
    <parent link="body_link"/>
    <child link="neck_link"/>
    <origin rpy="0 -0 0 " xyz="0 0 0.3535"/>
    <axis xyz="0 0 1"/>
    <!-- from -120 to 120 degrees-->
    <limit effort="100" lower="-2.09" upper="2.09" velocity="1.6"/>
    <dynamics damping="0.2" friction="0"/>
  </joint>
  <transmission name="neck_y_joint_trans">
    <type>transmission_interface/SimpleTransmission</type>
    <joint name="neck_y_joint">
      <!-- dupricated in kinetic -->
      <!--hardwareInterface>hardware_interface/EffortJointInterface</hardwareInterface-->
      <!--hardwareInterface>EffortJointInterface</hardwareInterface-->
      <hardwareInterface>VelocityJointInterface</hardwareInterface>
    </joint>
    <actuator name="neck_y_joint_motor">
      <!-- dupricated in kinetic -->
      <!--hardwareInterface>hardware_interface/EffortJointInterface</hardwareInterface-->
      <!--hardwareInterface>EffortJointInterface</hardwareInterface-->
      <hardwareInterface>VelocityJointInterface</hardwareInterface>
      <mechanicalReduction>1</mechanicalReduction>
    </actuator>
  </transmission>
  <gazebo reference="neck_y_joint">
    <implicitSpringDamper>0</implicitSpringDamper>
  </gazebo>
  <joint name="neck_p_joint" type="revolute">
    <parent link="neck_link"/>
    <child link="head_base_link"/>
    <origin rpy="0 -0 0 " xyz="0 0 0.1045"/>
    <axis xyz="0 1 0"/>
    <!-- from -15 to 55 degrees-->
    <limit effort="100" lower="-0.262" upper="0.96" velocity="2.1"/>
    <dynamics damping="0.2" friction="0"/>
  </joint>
  <transmission name="neck_p_joint_trans">
    <type>transmission_interface/SimpleTransmission</type>
    <joint name="neck_p_joint">
      <!-- dupricated in kinetic -->
      <!--hardwareInterface>hardware_interface/EffortJointInterface</hardwareInterface-->
      <!--hardwareInterface>EffortJointInterface</hardwareInterface-->
      <hardwareInterface>VelocityJointInterface</hardwareInterface>
    </joint>
    <actuator name="neck_p_joint_motor">
      <!-- dupricated in kinetic -->
      <!--hardwareInterface>hardware_interface/EffortJointInterface</hardwareInterface-->
      <!--hardwareInterface>EffortJointInterface</hardwareInterface-->
      <hardwareInterface>VelocityJointInterface</hardwareInterface>
      <mechanicalReduction>1</mechanicalReduction>
    </actuator>
  </transmission>
  <gazebo reference="neck_p_joint">
    <implicitSpringDamper>0</implicitSpringDamper>
  </gazebo>
  <joint name="neck_r_joint" type="revolute">
    <parent link="head_base_link"/>
    <child link="head_link"/>
    <origin rpy="0 -0 0 " xyz="0 0 0"/>
    <axis xyz="1 0 0"/>
    <!-- from -5 to 5 degrees-->
    <limit effort="100" lower="-0.087" upper="0.087" velocity="0.9"/>
    <dynamics damping="0.2" friction="0"/>
  </joint>
  <transmission name="neck_r_joint_trans">
    <type>transmission_interface/SimpleTransmission</type>
    <joint name="neck_r_joint">
      <!-- dupricated in kinetic -->
      <!--hardwareInterface>hardware_interface/EffortJointInterface</hardwareInterface-->
      <!--hardwareInterface>EffortJointInterface</hardwareInterface-->
      <hardwareInterface>VelocityJointInterface</hardwareInterface>
    </joint>
    <actuator name="neck_r_joint_motor">
      <!-- dupricated in kinetic -->
      <!--hardwareInterface>hardware_interface/EffortJointInterface</hardwareInterface-->
      <!--hardwareInterface>EffortJointInterface</hardwareInterface-->
      <hardwareInterface>VelocityJointInterface</hardwareInterface>
      <mechanicalReduction>1</mechanicalReduction>
    </actuator>
  </transmission>
  <gazebo reference="neck_r_joint">
    <implicitSpringDamper>0</implicitSpringDamper>
  </gazebo>
  <joint name="r_shoulder_p_joint" type="revolute">
    <parent link="body_link"/>
    <child link="r_shoulder_link"/>
    <origin rpy="0 -0 0 " xyz="-0.01815 -0.1342 0.3049"/>
    <axis xyz="0 0.984808 0.173648"/>
    <!-- from -88 to 15 degrees-->
    <limit effort="200" lower="-1.535" upper="0.261" velocity="0.4"/>
    <dynamics damping="0.2" friction="0"/>
  </joint>
  <transmission name="r_shoulder_p_joint_trans">
    <type>transmission_interface/SimpleTransmission</type>
    <joint name="r_shoulder_p_joint">
      <!-- dupricated in kinetic -->
      <!--hardwareInterface>hardware_interface/EffortJointInterface</hardwareInterface-->
      <!--hardwareInterface>EffortJointInterface</hardwareInterface-->
      <hardwareInterface>VelocityJointInterface</hardwareInterface>
    </joint>
    <actuator name="r_shoulder_p_joint_motor">
      <!-- dupricated in kinetic -->
      <!--hardwareInterface>hardware_interface/EffortJointInterface</hardwareInterface-->
      <!--hardwareInterface>EffortJointInterface</hardwareInterface-->
      <hardwareInterface>VelocityJointInterface</hardwareInterface>
      <mechanicalReduction>1</mechanicalReduction>
    </actuator>
  </transmission>
  <gazebo reference="r_shoulder_p_joint">
    <implicitSpringDamper>0</implicitSpringDamper>
  </gazebo>
  <joint name="r_shoulder_r_joint" type="revolute">
    <parent link="r_shoulder_link"/>
    <child link="r_shoulder_center"/>
    <origin rpy="0 -0 0 " xyz="0 -0.059778 0.028046"/>
    <axis xyz="1 0 0"/>
    <!-- from -90 to 0 degrees-->
    <limit effort="100" lower="-1.5707" upper="0" velocity="0.6"/>
    <dynamics damping="0.2" friction="0"/>
  </joint>
  <transmission name="r_shoulder_r_joint_trans">
    <type>transmission_interface/SimpleTransmission</type>
    <joint name="r_shoulder_r_joint">
      <!-- dupricated in kinetic -->
      <!--hardwareInterface>hardware_interface/EffortJointInterface</hardwareInterface-->
      <!--hardwareInterface>EffortJointInterface</hardwareInterface-->
      <hardwareInterface>VelocityJointInterface</hardwareInterface>
    </joint>
    <actuator name="r_shoulder_r_joint_motor">
      <!-- dupricated in kinetic -->
      <!--hardwareInterface>hardware_interface/EffortJointInterface</hardwareInterface-->
      <!--hardwareInterface>EffortJointInterface</hardwareInterface-->
      <hardwareInterface>VelocityJointInterface</hardwareInterface>
      <mechanicalReduction>1</mechanicalReduction>
    </actuator>
  </transmission>
  <gazebo reference="r_shoulder_r_joint">
    <implicitSpringDamper>0</implicitSpringDamper>
  </gazebo>
  <joint name="r_shoulder_y_joint" type="revolute">
    <parent link="r_shoulder_center"/>
    <child link="r_upperarm_link"/>
    <origin rpy="0 -0 0 " xyz="0 0.010 -0.127"/>
    <axis xyz="0 0 1"/>
    <!-- from -45 to 180 degrees-->
    <limit effort="100" lower="-0.785398" upper="1.5707" velocity="1.2"/>
    <dynamics damping="0.2" friction="0"/>
  </joint>
  <transmission name="r_shoulder_y_joint_trans">
    <type>transmission_interface/SimpleTransmission</type>
    <joint name="r_shoulder_y_joint">
      <!-- dupricated in kinetic -->
      <!--hardwareInterface>hardware_interface/EffortJointInterface</hardwareInterface-->
      <!--hardwareInterface>EffortJointInterface</hardwareInterface-->
      <hardwareInterface>VelocityJointInterface</hardwareInterface>
    </joint>
    <actuator name="r_shoulder_y_joint_motor">
      <!-- dupricated in kinetic -->
      <!--hardwareInterface>hardware_interface/EffortJointInterface</hardwareInterface-->
      <!--hardwareInterface>EffortJointInterface</hardwareInterface-->
      <hardwareInterface>VelocityJointInterface</hardwareInterface>
      <mechanicalReduction>1</mechanicalReduction>
    </actuator>
  </transmission>
  <gazebo reference="r_shoulder_y_joint">
    <implicitSpringDamper>0</implicitSpringDamper>
  </gazebo>
  <joint name="r_elbow_joint" type="revolute">
    <parent link="r_upperarm_link"/>
    <child link="r_elbow_link"/>
    <origin rpy="0 -0 0 " xyz="0.035 0 -0.1625"/>
    <axis xyz="0 1 0"/>
    <!-- from -171 to 0 degrees-->
    <limit effort="100" lower="-3.0" upper="0" velocity="1.2"/>
    <dynamics damping="0.2" friction="0"/>
  </joint>
  <transmission name="r_elbow_joint_trans">
    <type>transmission_interface/SimpleTransmission</type>
    <joint name="r_elbow_joint">
      <!-- dupricated in kinetic -->
      <!--hardwareInterface>hardware_interface/EffortJointInterface</hardwareInterface-->
      <!--hardwareInterface>EffortJointInterface</hardwareInterface-->
      <hardwareInterface>VelocityJointInterface</hardwareInterface>
    </joint>
    <actuator name="r_elbow_joint_motor">
      <!-- dupricated in kinetic -->
      <!--hardwareInterface>hardware_interface/EffortJointInterface</hardwareInterface-->
      <!--hardwareInterface>EffortJointInterface</hardwareInterface-->
      <hardwareInterface>VelocityJointInterface</hardwareInterface>
      <mechanicalReduction>1</mechanicalReduction>
    </actuator>
  </transmission>
  <gazebo reference="r_elbow_joint">
    <implicitSpringDamper>0</implicitSpringDamper>
  </gazebo>
  <joint name="r_wrist_y_joint" type="revolute">
    <parent link="r_elbow_link"/>
    <child link="r_forearm_link"/>
    <origin rpy="0 -0 0 " xyz="-0.035 0 -0.070"/>
    <axis xyz="0 0 1"/>
    <!-- from -180 to 180 degrees-->
    <limit effort="100" lower="-1.5707" upper="1.5707" velocity="1.3"/>
    <dynamics damping="0.2" friction="0"/>
  </joint>
  <transmission name="r_wrist_y_joint_trans">
    <type>transmission_interface/SimpleTransmission</type>
    <joint name="r_wrist_y_joint">
      <!-- dupricated in kinetic -->
      <!--hardwareInterface>hardware_interface/EffortJointInterface</hardwareInterface-->
      <!--hardwareInterface>EffortJointInterface</hardwareInterface-->
      <hardwareInterface>VelocityJointInterface</hardwareInterface>
    </joint>
    <actuator name="r_wrist_y_joint_motor">
      <!-- dupricated in kinetic -->
      <!--hardwareInterface>hardware_interface/EffortJointInterface</hardwareInterface-->
      <!--hardwareInterface>EffortJointInterface</hardwareInterface-->
      <hardwareInterface>VelocityJointInterface</hardwareInterface>
      <mechanicalReduction>1</mechanicalReduction>
    </actuator>
  </transmission>
  <gazebo reference="r_wrist_y_joint">
    <implicitSpringDamper>0</implicitSpringDamper>
  </gazebo>
  <joint name="r_wrist_p_joint" type="revolute">
    <parent link="r_forearm_link"/>
    <child link="r_wrist_center"/>
    <origin rpy="0 -0 0 " xyz="0 0 -0.1955"/>
    <axis xyz="0 1 0"/>
    <!-- from -5 to 5 degrees-->
    <limit effort="100" lower="-0.087" upper="0.087" velocity="0.9"/>
    <dynamics damping="0.2" friction="0"/>
  </joint>
  <transmission name="r_wrist_p_joint_trans">
    <type>transmission_interface/SimpleTransmission</type>
    <joint name="r_wrist_p_joint">
      <!-- dupricated in kinetic -->
      <!--hardwareInterface>hardware_interface/EffortJointInterface</hardwareInterface-->
      <!--hardwareInterface>EffortJointInterface</hardwareInterface-->
      <hardwareInterface>VelocityJointInterface</hardwareInterface>
    </joint>
    <actuator name="r_wrist_p_joint_motor">
      <!-- dupricated in kinetic -->
      <!--hardwareInterface>hardware_interface/EffortJointInterface</hardwareInterface-->
      <!--hardwareInterface>EffortJointInterface</hardwareInterface-->
      <hardwareInterface>VelocityJointInterface</hardwareInterface>
      <mechanicalReduction>1</mechanicalReduction>
    </actuator>
  </transmission>
  <gazebo reference="r_wrist_p_joint">
    <implicitSpringDamper>0</implicitSpringDamper>
  </gazebo>
  <joint name="r_wrist_r_joint" type="revolute">
    <parent link="r_wrist_center"/>
    <child link="r_hand_yaw_link"/>
    <origin rpy="0 -0 0 " xyz="0 0 0"/>
    <axis xyz="1 0 0"/>
    <!-- from -25 to 85 degrees-->
    <limit effort="100" lower="-0.436" upper="1.484" velocity="2.1"/>
    <dynamics damping="0.2" friction="0"/>
  </joint>
  <transmission name="r_wrist_r_joint_trans">
    <type>transmission_interface/SimpleTransmission</type>
    <joint name="r_wrist_r_joint">
      <!-- dupricated in kinetic -->
      <!--hardwareInterface>hardware_interface/EffortJointInterface</hardwareInterface-->
      <!--hardwareInterface>EffortJointInterface</hardwareInterface-->
      <hardwareInterface>VelocityJointInterface</hardwareInterface>
    </joint>
    <actuator name="r_wrist_r_joint_motor">
      <!-- dupricated in kinetic -->
      <!--hardwareInterface>hardware_interface/EffortJointInterface</hardwareInterface-->
      <!--hardwareInterface>EffortJointInterface</hardwareInterface-->
      <hardwareInterface>VelocityJointInterface</hardwareInterface>
      <mechanicalReduction>1</mechanicalReduction>
    </actuator>
  </transmission>
  <gazebo reference="r_wrist_r_joint">
    <implicitSpringDamper>0</implicitSpringDamper>
  </gazebo>
  <!-- ============================   hand_yaw   ============================ -->
  <!-- prefix is "r" or "l" -->
  <!-- reflect=1 is rightside, reflect=-1 is leftside -->
  <link name="r_hand_yaw_link">
    <visual>
      <origin rpy="0 1.57079632679 1.57079632679" xyz="0.0 0 0"/>
      <geometry>
        <mesh filename="package://aero_description/meshes/hand_yaw/wrist.dae" scale="1 1 1"/>
      </geometry>
    </visual>
    <collision>
      <origin rpy="0 1.57079632679 1.57079632679" xyz="0 0 0"/>
      <geometry>
        <mesh filename="package://aero_description/meshes/hand_yaw/wrist.dae" scale="1 1 1"/>
      </geometry>
    </collision>
    <inertial>
      <mass value="0.183"/>
      <!-- original version -->
      <!--origin xyz="0 0 -0.0875" rpy="0 -0 0"/>
      <inertia ixx="0.000601" ixy="0" ixz="0" iyy="0.00055" iyz="0" izz="0.000102"/-->
      <!-- just fixed for gazebo / aim to increase z axis inertia-->
      <origin rpy="0 -0 0" xyz="0 0.014 -0.02"/>
      <inertia ixx="0.0005" ixy="0" ixz="0" iyy="0.0005" iyz="0" izz="0.0007"/>
    </inertial>
  </link>
  <gazebo reference="r_hand_yaw_link">
    <mu1>0.9</mu1>
    <mu2>0.9</mu2>
  </gazebo>
  <joint name="r_hand_y_joint" type="revolute">
    <parent link="r_hand_yaw_link"/>
    <child link="r_hand_link"/>
    <origin rpy="0 0 0" xyz="0 0 -0.04"/>
    <axis xyz="0 0 1"/>
    <limit effort="100" lower="-2.0" upper="2.0" velocity="3.1"/>
    <dynamics damping="0.2" friction="0"/>
  </joint>
  <transmission name="r_hand_y_joint_trans">
    <type>transmission_interface/SimpleTransmission</type>
    <joint name="r_hand_y_joint">
      <!-- dupricated in kinetic -->
      <!--hardwareInterface>hardware_interface/EffortJointInterface</hardwareInterface-->
      <!--hardwareInterface>EffortJointInterface</hardwareInterface-->
      <hardwareInterface>VelocityJointInterface</hardwareInterface>
    </joint>
    <actuator name="r_hand_y_joint_motor">
      <!-- dupricated in kinetic -->
      <!--hardwareInterface>hardware_interface/EffortJointInterface</hardwareInterface-->
      <!--hardwareInterface>EffortJointInterface</hardwareInterface-->
      <hardwareInterface>VelocityJointInterface</hardwareInterface>
      <mechanicalReduction>1</mechanicalReduction>
    </actuator>
  </transmission>
  <gazebo reference="r_hand_y_joint">
    <implicitSpringDamper>0</implicitSpringDamper>
  </gazebo>
  <!-- ============================   hand_yaw   ============================ -->
  <!-- prefix is "r" or "l" -->
  <!-- reflect=1 is rightside, reflect=-1 is leftside -->
  <link name="l_hand_yaw_link">
    <visual>
      <origin rpy="0 1.57079632679 -1.57079632679" xyz="0.0 0 0"/>
      <geometry>
        <mesh filename="package://aero_description/meshes/hand_yaw_s/wrist.dae" scale="1 1 1"/>
      </geometry>
    </visual>
    <collision>
      <origin rpy="0 1.57079632679 -1.57079632679" xyz="0 0 0"/>
      <geometry>
        <mesh filename="package://aero_description/meshes/hand_yaw_s/wrist.dae" scale="1 1 1"/>
      </geometry>
    </collision>
    <inertial>
      <mass value="0.183"/>
      <!-- original version -->
      <!--origin xyz="0 0 -0.0875" rpy="0 -0 0"/>
      <inertia ixx="0.000601" ixy="0" ixz="0" iyy="0.00055" iyz="0" izz="0.000102"/-->
      <!-- just fixed for gazebo / aim to increase z axis inertia-->
      <origin rpy="0 -0 0" xyz="0 0.014 -0.02"/>
      <inertia ixx="0.003" ixy="0" ixz="0" iyy="0.003" iyz="0" izz="0.005"/>
    </inertial>
  </link>
  <gazebo reference="l_hand_yaw_link">
    <mu1>0.9</mu1>
    <mu2>0.9</mu2>
  </gazebo>
  <joint name="l_hand_y_joint" type="revolute">
    <parent link="l_hand_yaw_link"/>
    <child link="l_hand_link"/>
    <origin rpy="0 0 0" xyz="0 0 0"/>
    <axis xyz="0 0 1"/>
    <!--limit lower="-2.0" upper="2.0" effort="100" velocity="2.0" /-->
    <limit effort="100" lower="-3.2" upper="3.2" velocity="2.0"/>
    <dynamics damping="0.2" friction="0"/>
  </joint>
  <transmission name="l_hand_y_joint_trans">
    <type>transmission_interface/SimpleTransmission</type>
    <joint name="l_hand_y_joint">
      <!-- dupricated in kinetic -->
      <!--hardwareInterface>hardware_interface/EffortJointInterface</hardwareInterface-->
      <!--hardwareInterface>EffortJointInterface</hardwareInterface-->
      <hardwareInterface>VelocityJointInterface</hardwareInterface>
    </joint>
    <actuator name="l_hand_y_joint_motor">
      <!-- dupricated in kinetic -->
      <!--hardwareInterface>hardware_interface/EffortJointInterface</hardwareInterface-->
      <!--hardwareInterface>EffortJointInterface</hardwareInterface-->
      <hardwareInterface>VelocityJointInterface</hardwareInterface>
      <mechanicalReduction>1</mechanicalReduction>
    </actuator>
  </transmission>
  <gazebo reference="l_hand_y_joint">
    <implicitSpringDamper>0</implicitSpringDamper>
  </gazebo>
  <!-- ============================   seed_hand   ============================ -->
  <!-- prefix is "r" or "l" -->
  <!-- reflect=1 is rightside, reflect=-1 is leftside -->
  <link name="r_hand_link">
    <visual>
      <origin rpy="3.14159265359 -0 1.57079632679" xyz="0 0 0"/>
      <geometry>
        <mesh filename="package://aero_description/meshes/seed_hand/RARM_LINK7_mesh.dae" scale="1 1 1"/>
      </geometry>
    </visual>
    <collision>
      <origin rpy="3.14159265359 -0 1.57079632679" xyz="0 0 -0.025"/>
      <geometry>
        <box size="0.060 0.030 0.050"/>
      </geometry>
    </collision>
    <collision>
      <origin rpy="3.14159265359 0.9 1.57079632679" xyz="0 0 -0.063"/>
      <geometry>
        <box size="0.020 0.030 0.075"/>
      </geometry>
    </collision>
    <inertial>
      <mass value="0.183"/>
      <origin rpy="0 -0 0" xyz="0 0 -0.0875"/>
      <!-- TODO: check -->
      <inertia ixx="0.000601" ixy="0" ixz="0" iyy="0.00055" iyz="0" izz="0.000102"/>
    </inertial>
  </link>
  <gazebo reference="r_hand_link">
    <mu1>0.9</mu1>
    <mu2>0.9</mu2>
  </gazebo>
  <link name="r_indexbase_link">
    <visual>
      <origin rpy="3.14159265359 0 1.57079632679" xyz="0 0 0"/>
      <geometry>
        <mesh filename="package://aero_description/meshes/seed_hand/RARM_INDEX_LINK1_mesh.dae" scale="1 1 1"/>
      </geometry>
    </visual>
    <collision>
      <origin rpy="3.14159265359 0 1.57079632679" xyz="0 -0.004 -0.0123"/>
      <geometry>
        <!--mesh filename="package://aero_description/meshes/seed_hand/RARM_INDEX_LINK1_mesh.dae" scale="1 1 1" /-->
        <!--box size="0.028 0.0615 0.074" /-->
        <box size="0.020 0.0615 0.054"/>
      </geometry>
    </collision>
    <inertial>
      <mass value="0.1"/>
      <origin rpy="0 -0 0" xyz="0 0 -0.023"/>
      <inertia ixx="0.0001" ixy="0" ixz="0" iyy="0.0001" iyz="0" izz="0.0001"/>
    </inertial>
  </link>
  <gazebo reference="r_indextbase_link">
    <mu1>0.9</mu1>
    <mu2>0.9</mu2>
  </gazebo>
  <link name="r_indexmid_link">
    <!-- dummy link, backward compatibility ??? -->
    <inertial>
      <mass value="0.1"/>
      <origin rpy="0 -0 0" xyz="0 0 -0.023"/>
      <inertia ixx="0.0001" ixy="0" ixz="0" iyy="0.0001" iyz="0" izz="0.0001"/>
    </inertial>
  </link>
  <gazebo reference="r_indexmid_link">
    <mu1>0.9</mu1>
    <mu2>0.9</mu2>
  </gazebo>
  <link name="r_indexend_link">
    <visual>
      <origin rpy="3.14159265359 0 1.57079632679" xyz="0 0 0"/>
      <geometry>
        <mesh filename="package://aero_description/meshes/seed_hand/RARM_INDEX_LINK3_mesh.dae" scale="1 1 1"/>
      </geometry>
    </visual>
    <collision>
      <origin rpy="3.14159265359 0 1.57079632679" xyz="0 0 -0.0225"/>
      <geometry>
        <!--mesh filename="package://aero_description/meshes/seed_hand/RARM_INDEX_LINK3_mesh.dae" scale="1 1 1" /-->
        <box size="0.020 0.0596 0.065"/>
      </geometry>
    </collision>
    <inertial>
      <mass value="0.07"/>
      <origin rpy="0 -0 0" xyz="0 0.014 -0.0225"/>
      <inertia ixx="0.0014" ixy="0" ixz="0" iyy="0.0001" iyz="0" izz="0.0001"/>
    </inertial>
  </link>
  <gazebo reference="r_indexend_link">
    <mu1>0.9</mu1>
    <mu2>0.9</mu2>
  </gazebo>
  <link name="r_thumb_link">
    <visual>
      <origin rpy="-3.14159265359 0 1.57079632679" xyz="0 0 0"/>
      <geometry>
        <mesh filename="package://aero_description/meshes/seed_hand/RARM_THUMB_LINK_mesh.dae" scale="1 1 1"/>
      </geometry>
    </visual>
    <collision>
      <origin rpy="-3.14159265359 0 1.57079632679" xyz="0.0 -0.003 -0.0375"/>
      <geometry>
        <!--mesh filename="package://aero_description/meshes/seed_hand/RARM_THUMB_LINK_mesh.dae" scale="1 1 1" /-->
        <box size="0.032 0.054 0.105"/>
      </geometry>
    </collision>
    <inertial>
      <mass value="0.1"/>
      <origin rpy="0 -0 0" xyz="0 0 -0.04"/>
      <inertia ixx="0.0001" ixy="0" ixz="0" iyy="0.0001" iyz="0" izz="0.0001"/>
    </inertial>
  </link>
  <gazebo reference="r_thumb_link">
    <mu1>0.9</mu1>
    <mu2>0.9</mu2>
  </gazebo>
  <joint name="r_indexbase_joint" type="revolute">
    <parent link="r_hand_link"/>
    <child link="r_indexbase_link"/>
    <origin rpy="1.0472 -0 0" xyz="0 -0.02 -0.08"/>
    <axis xyz="1 0 0"/>
    <limit effort="25" lower="-0.872665" upper="0.872665" velocity="0.5"/>
    <dynamics damping="0.2" friction="0"/>
  </joint>
  <transmission name="r_indexbase_joint_trans">
    <type>transmission_interface/SimpleTransmission</type>
    <joint name="r_indexbase_joint">
      <!-- dupricated in kinetic -->
      <!--hardwareInterface>hardware_interface/EffortJointInterface</hardwareInterface-->
      <!--hardwareInterface>EffortJointInterface</hardwareInterface-->
      <hardwareInterface>VelocityJointInterface</hardwareInterface>
    </joint>
    <actuator name="r_indexbase_joint_motor">
      <!-- dupricated in kinetic -->
      <!--hardwareInterface>hardware_interface/EffortJointInterface</hardwareInterface-->
      <!--hardwareInterface>EffortJointInterface</hardwareInterface-->
      <hardwareInterface>VelocityJointInterface</hardwareInterface>
      <mechanicalReduction>1</mechanicalReduction>
    </actuator>
  </transmission>
  <gazebo reference="r_indexbase_joint">
    <implicitSpringDamper>0</implicitSpringDamper>
  </gazebo>
  <joint name="r_indexmid_joint" type="revolute">
    <!-- dummy joint, should be fixed joint -->
    <parent link="r_hand_link"/>
    <child link="r_indexmid_link"/>
    <origin rpy="0 -0 0 " xyz="0 0 0"/>
    <axis xyz="1 0 0"/>
    <limit effort="25" lower="-3.14159" upper="3.14159" velocity="0.5"/>
    <dynamics damping="0.2" friction="0"/>
  </joint>
  <transmission name="r_indexmid_joint_trans">
    <type>transmission_interface/SimpleTransmission</type>
    <joint name="r_indexmid_joint">
      <!-- dupricated in kinetic -->
      <!--hardwareInterface>hardware_interface/EffortJointInterface</hardwareInterface-->
      <!--hardwareInterface>EffortJointInterface</hardwareInterface-->
      <hardwareInterface>VelocityJointInterface</hardwareInterface>
    </joint>
    <actuator name="r_indexmid_joint_motor">
      <!-- dupricated in kinetic -->
      <!--hardwareInterface>hardware_interface/EffortJointInterface</hardwareInterface-->
      <!--hardwareInterface>EffortJointInterface</hardwareInterface-->
      <hardwareInterface>VelocityJointInterface</hardwareInterface>
      <mechanicalReduction>1</mechanicalReduction>
    </actuator>
  </transmission>
  <gazebo reference="r_indexmid_joint">
    <implicitSpringDamper>0</implicitSpringDamper>
  </gazebo>
  <!--xacro:gazebo_joint_reference joint_name="${prefix}_indexmid_joint" /-->
  <joint name="r_indexend_joint" type="revolute">
    <parent link="r_indexbase_link"/>
    <child link="r_indexend_link"/>
    <origin rpy="0.17 -0 0 " xyz="0 -0.004 -0.049840"/>
    <axis xyz="1 0 0"/>
    <limit effort="25" lower="-3.14159" upper="3.14159" velocity="0.5"/>
    <dynamics damping="0.2" friction="0"/>
  </joint>
  <transmission name="r_indexend_joint_trans">
    <type>transmission_interface/SimpleTransmission</type>
    <joint name="r_indexend_joint">
      <!-- dupricated in kinetic -->
      <!--hardwareInterface>hardware_interface/EffortJointInterface</hardwareInterface-->
      <!--hardwareInterface>EffortJointInterface</hardwareInterface-->
      <hardwareInterface>VelocityJointInterface</hardwareInterface>
    </joint>
    <actuator name="r_indexend_joint_motor">
      <!-- dupricated in kinetic -->
      <!--hardwareInterface>hardware_interface/EffortJointInterface</hardwareInterface-->
      <!--hardwareInterface>EffortJointInterface</hardwareInterface-->
      <hardwareInterface>VelocityJointInterface</hardwareInterface>
      <mechanicalReduction>1</mechanicalReduction>
    </actuator>
  </transmission>
  <gazebo reference="r_indexend_joint">
    <implicitSpringDamper>0</implicitSpringDamper>
  </gazebo>
  <!--xacro:gazebo_joint_reference joint_name="${prefix}_indexend_joint" /-->
  <joint name="r_thumb_joint" type="revolute">
    <parent link="r_hand_link"/>
    <child link="r_thumb_link"/>
    <origin rpy="0.698 -0 0 " xyz="0 0.02 -0.030"/>
    <axis xyz="1 0 0"/>
    <limit effort="25" lower="-0.872665" upper="0.872665" velocity="0.5"/>
    <dynamics damping="0.2" friction="0"/>
  </joint>
  <transmission name="r_thumb_joint_trans">
    <type>transmission_interface/SimpleTransmission</type>
    <joint name="r_thumb_joint">
      <!-- dupricated in kinetic -->
      <!--hardwareInterface>hardware_interface/EffortJointInterface</hardwareInterface-->
      <!--hardwareInterface>EffortJointInterface</hardwareInterface-->
      <hardwareInterface>VelocityJointInterface</hardwareInterface>
    </joint>
    <actuator name="r_thumb_joint_motor">
      <!-- dupricated in kinetic -->
      <!--hardwareInterface>hardware_interface/EffortJointInterface</hardwareInterface-->
      <!--hardwareInterface>EffortJointInterface</hardwareInterface-->
      <hardwareInterface>VelocityJointInterface</hardwareInterface>
      <mechanicalReduction>1</mechanicalReduction>
    </actuator>
  </transmission>
  <gazebo reference="r_thumb_joint">
    <implicitSpringDamper>0</implicitSpringDamper>
  </gazebo>
  <!-- for ik eef link-->
  <link name="r_eef_grasp_link"/>
  <link name="r_eef_pick_link"/>
  <link name="r_thumb_tip_link"/>
  <link name="r_index_tip_link"/>
  <!-- for ik eef link-->
  <!-- for ik eef connector-->
  <joint name="r_eef_grasp_joint" type="fixed">
    <parent link="r_hand_link"/>
    <child link="r_eef_grasp_link"/>
    <origin rpy="0 1.5708 0 " xyz="0.0 0.03 -0.08"/>
  </joint>
  <joint name="r_eef_pick_joint" type="fixed">
    <parent link="r_hand_link"/>
    <child link="r_eef_pick_link"/>
    <origin rpy="0 1.5708 0 " xyz="0.0 0.05 -0.12"/>
  </joint>
  <joint name="r_thumb_tip_joint" type="fixed">
    <parent link="r_thumb_link"/>
    <child link="r_thumb_tip_link"/>
    <origin rpy="0 0 0 " xyz="0.0 0.02 -0.085"/>
  </joint>
  <joint name="r_index_tip_joint" type="fixed">
    <parent link="r_indexend_link"/>
    <child link="r_index_tip_link"/>
    <origin rpy="0 0 0 " xyz="0.0 0.0 -0.045"/>
  </joint>
  <!-- for ik eef connector-->
  <!-- ============================   Hand(trx_s)   ============================ -->
  <!-- prefix is "r" or "l" -->
  <!-- reflect=1 is rightside, reflect=-1 is leftside -->
  <link name="l_hand_link">
    <visual>
      <origin rpy="0 -0 3.14159265359" xyz="0 0 0"/>
      <geometry>
        <mesh filename="package://aero_description/meshes/trx_s/RARM_LINK7_mesh.dae" scale="1 1 1"/>
      </geometry>
    </visual>
    <collision>
      <origin rpy="-0.7 0 0" xyz="0 0 -0.093"/>
      <geometry>
        <box size="0.036 0.070 0.030"/>
      </geometry>
    </collision>
    <collision>
      <origin rpy="0.1 0 0" xyz="0 0.007 -0.055"/>
      <geometry>
        <box size="0.036 0.050 0.070"/>
      </geometry>
    </collision>
    <inertial>
      <mass value="0.183"/>
      <origin rpy="0 -0 0" xyz="0 0 -0.0875"/>
      <inertia ixx="0.000601" ixy="0" ixz="0" iyy="0.00055" iyz="0" izz="0.000102"/>
    </inertial>
  </link>
  <gazebo reference="l_hand_link">
    <mu1>0.9</mu1>
    <mu2>0.9</mu2>
  </gazebo>
  <link name="l_indexbase_link">
    <visual>
      <origin rpy="0 -0 3.14159265359" xyz="0 -0.013 0.115"/>
      <geometry>
        <mesh filename="package://aero_description/meshes/trx_s/RARM_INDEX_LINK1_mesh.dae" scale="1 1 1"/>
      </geometry>
    </visual>
    <collision>
      <origin rpy="0.85 0 0" xyz="0 -0.013494 -0.021422"/>
      <geometry>
        <box size="0.041 0.061 0.016"/>
        <!-- 0.85 -->
      </geometry>
    </collision>
    <inertial>
      <mass value="0.1"/>
      <origin rpy="0 0 0" xyz="0 -0.014 -0.021"/>
      <inertia ixx="0.001" ixy="0" ixz="0" iyy="0.0001" iyz="0" izz="0.0001"/>
    </inertial>
  </link>
  <gazebo reference="l_indexbase_link">
    <mu1>0.9</mu1>
    <mu2>0.9</mu2>
  </gazebo>
  <link name="l_indexmid_link">
    <visual>
      <origin rpy="0 -0 3.14159265359" xyz="0 0.015754 0.149615"/>
      <geometry>
        <mesh filename="package://aero_description/meshes/trx_s/RARM_INDEX_LINK2_mesh.dae" scale="1 1 1"/>
      </geometry>
    </visual>
    <collision>
      <origin rpy="0.3 0 0" xyz="0 -0.014 -0.008"/>
      <!-- 0.3 -->
      <geometry>
        <box size="0.034 0.030 0.016"/>
      </geometry>
    </collision>
    <inertial>
      <mass value="0.1"/>
      <origin rpy="0 0 0" xyz="0 -0.014 -0.008"/>
      <inertia ixx="0.001" ixy="0" ixz="0" iyy="0.0001" iyz="0" izz="0.0001"/>
    </inertial>
  </link>
  <gazebo reference="l_indexmid_link">
    <mu1>0.9</mu1>
    <mu2>0.9</mu2>
  </gazebo>
  <link name="l_indexend_link">
    <visual>
      <origin rpy="0 -0 3.14159265359" xyz="0 0.03747 0.162972"/>
      <geometry>
        <mesh filename="package://aero_description/meshes/trx_s/RARM_INDEX_LINK3_mesh.dae" scale="1 1 1"/>
      </geometry>
    </visual>
    <collision>
      <origin rpy="0 0 0" xyz="0 -0.013 0.004"/>
      <!-- 0.0 -->
      <geometry>
        <box size="0.040 0.028 0.016"/>
      </geometry>
    </collision>
    <inertial>
      <mass value="0.1"/>
      <origin rpy="0 0 0" xyz="0 -0.02 0"/>
      <inertia ixx="0.0001" ixy="0" ixz="0" iyy="0.0001" iyz="0" izz="0.0001"/>
    </inertial>
  </link>
  <gazebo reference="l_indexend_link">
    <mu1>0.9</mu1>
    <mu2>0.9</mu2>
  </gazebo>
  <link name="l_thumb_link">
    <visual>
      <origin rpy="0 -0 3.14159265359" xyz="0 0.022355 0.079645"/>
      <geometry>
        <mesh filename="package://aero_description/meshes/trx_s/RARM_THUMB_LINK_mesh.dae" scale="1 1 1"/>
      </geometry>
    </visual>
    <collision>
      <origin rpy="-0.63 0 0" xyz="0.0 -0.019645 -0.010355"/>
      <geometry>
        <box size="0.012 0.008 0.050"/>
      </geometry>
    </collision>
    <collision>
      <origin rpy="-0.1 0 0" xyz="0.0 -0.035645 -0.050355"/>
      <geometry>
        <box size="0.012 0.008 0.050"/>
      </geometry>
    </collision>
    <inertial>
      <mass value="0.1"/>
      <origin rpy="0 0 0" xyz="0 -0.05 -0.06"/>
      <inertia ixx="0.001" ixy="0" ixz="0" iyy="0.0001" iyz="0" izz="0.0001"/>
    </inertial>
  </link>
  <gazebo reference="l_thumb_link">
    <mu1>0.9</mu1>
    <mu2>0.9</mu2>
  </gazebo>
  <joint name="l_indexbase_joint" type="revolute">
    <parent link="l_hand_link"/>
    <child link="l_indexbase_link"/>
    <origin rpy="0 -0 0 " xyz="0 0.013 -0.115"/>
    <axis xyz="1 0 0"/>
    <limit effort="100" lower="-0.872665" upper="0.872665" velocity="0.5"/>
    <dynamics damping="0.2" friction="0"/>
  </joint>
  <transmission name="l_indexbase_joint_trans">
    <type>transmission_interface/SimpleTransmission</type>
    <joint name="l_indexbase_joint">
      <!-- dupricated in kinetic -->
      <!--hardwareInterface>hardware_interface/EffortJointInterface</hardwareInterface-->
      <!--hardwareInterface>EffortJointInterface</hardwareInterface-->
      <hardwareInterface>VelocityJointInterface</hardwareInterface>
    </joint>
    <actuator name="l_indexbase_joint_motor">
      <!-- dupricated in kinetic -->
      <!--hardwareInterface>hardware_interface/EffortJointInterface</hardwareInterface-->
      <!--hardwareInterface>EffortJointInterface</hardwareInterface-->
      <hardwareInterface>VelocityJointInterface</hardwareInterface>
      <mechanicalReduction>1</mechanicalReduction>
    </actuator>
  </transmission>
  <gazebo reference="l_indexbase_joint">
    <implicitSpringDamper>0</implicitSpringDamper>
  </gazebo>
  <joint name="l_indexmid_joint" type="revolute">
    <parent link="l_indexbase_link"/>
    <child link="l_indexmid_link"/>
    <origin rpy="0 -0 0 " xyz="0 -0.028754 -0.034615"/>
    <axis xyz="1 0 0"/>
    <limit effort="100" lower="-3.14159" upper="3.14159" velocity="0.5"/>
    <dynamics damping="0.2" friction="0"/>
  </joint>
  <transmission name="l_indexmid_joint_trans">
    <type>transmission_interface/SimpleTransmission</type>
    <joint name="l_indexmid_joint">
      <!-- dupricated in kinetic -->
      <!--hardwareInterface>hardware_interface/EffortJointInterface</hardwareInterface-->
      <!--hardwareInterface>EffortJointInterface</hardwareInterface-->
      <hardwareInterface>VelocityJointInterface</hardwareInterface>
    </joint>
    <actuator name="l_indexmid_joint_motor">
      <!-- dupricated in kinetic -->
      <!--hardwareInterface>hardware_interface/EffortJointInterface</hardwareInterface-->
      <!--hardwareInterface>EffortJointInterface</hardwareInterface-->
      <hardwareInterface>VelocityJointInterface</hardwareInterface>
      <mechanicalReduction>1</mechanicalReduction>
    </actuator>
  </transmission>
  <gazebo reference="l_indexmid_joint">
    <implicitSpringDamper>0</implicitSpringDamper>
  </gazebo>
  <joint name="l_indexend_joint" type="revolute">
    <parent link="l_indexmid_link"/>
    <child link="l_indexend_link"/>
    <origin rpy="0 -0 0 " xyz="0 -0.021716 -0.013357"/>
    <axis xyz="1 0 0"/>
    <limit effort="100" lower="-3.14159" upper="3.14159" velocity="0.5"/>
    <dynamics damping="0.2" friction="0"/>
  </joint>
  <transmission name="l_indexend_joint_trans">
    <type>transmission_interface/SimpleTransmission</type>
    <joint name="l_indexend_joint">
      <!-- dupricated in kinetic -->
      <!--hardwareInterface>hardware_interface/EffortJointInterface</hardwareInterface-->
      <!--hardwareInterface>EffortJointInterface</hardwareInterface-->
      <hardwareInterface>VelocityJointInterface</hardwareInterface>
    </joint>
    <actuator name="l_indexend_joint_motor">
      <!-- dupricated in kinetic -->
      <!--hardwareInterface>hardware_interface/EffortJointInterface</hardwareInterface-->
      <!--hardwareInterface>EffortJointInterface</hardwareInterface-->
      <hardwareInterface>VelocityJointInterface</hardwareInterface>
      <mechanicalReduction>1</mechanicalReduction>
    </actuator>
  </transmission>
  <gazebo reference="l_indexend_joint">
    <implicitSpringDamper>0</implicitSpringDamper>
  </gazebo>
  <joint name="l_thumb_joint" type="revolute">
    <parent link="l_hand_link"/>
    <child link="l_thumb_link"/>
    <origin rpy="0 -0 0 " xyz="0 -0.022355 -0.079645"/>
    <axis xyz="1 0 0"/>
    <limit effort="100" lower="-0.872665" upper="0.872665" velocity="0.5"/>
    <dynamics damping="0.2" friction="0"/>
  </joint>
  <transmission name="l_thumb_joint_trans">
    <type>transmission_interface/SimpleTransmission</type>
    <joint name="l_thumb_joint">
      <!-- dupricated in kinetic -->
      <!--hardwareInterface>hardware_interface/EffortJointInterface</hardwareInterface-->
      <!--hardwareInterface>EffortJointInterface</hardwareInterface-->
      <hardwareInterface>VelocityJointInterface</hardwareInterface>
    </joint>
    <actuator name="l_thumb_joint_motor">
      <!-- dupricated in kinetic -->
      <!--hardwareInterface>hardware_interface/EffortJointInterface</hardwareInterface-->
      <!--hardwareInterface>EffortJointInterface</hardwareInterface-->
      <hardwareInterface>VelocityJointInterface</hardwareInterface>
      <mechanicalReduction>1</mechanicalReduction>
    </actuator>
  </transmission>
  <gazebo reference="l_thumb_joint">
    <implicitSpringDamper>0</implicitSpringDamper>
  </gazebo>
  <!-- for ik eef link-->
  <link name="l_eef_grasp_link"/>
  <link name="l_eef_pick_link"/>
  <link name="l_thumb_tip_link"/>
  <link name="l_index_tip_link"/>
  <!-- for ik eef link-->
  <!-- for ik eef connector-->
  <joint name="l_eef_grasp_joint" type="fixed">
    <parent link="l_hand_link"/>
    <child link="l_eef_grasp_link"/>
    <origin rpy="0 1.5708 0 " xyz="0.0 -0.04 -0.14"/>
  </joint>
  <joint name="l_eef_pick_joint" type="fixed">
    <parent link="l_hand_link"/>
    <child link="l_eef_pick_link"/>
    <origin rpy="0 1.5708 0 " xyz="0.0 -0.07 -0.16"/>
  </joint>
  <joint name="l_thumb_tip_joint" type="fixed">
    <parent link="l_thumb_link"/>
    <child link="l_thumb_tip_link"/>
    <origin rpy="0 0 0 " xyz="0.0 -0.035 -0.085"/>
  </joint>
  <joint name="l_index_tip_joint" type="fixed">
    <parent link="l_indexend_link"/>
    <child link="l_index_tip_link"/>
    <origin rpy="0 0 0 " xyz="0.0 -0.02 0.0"/>
  </joint>
  <!-- for ik eef connector-->
  <joint name="upper_lower_connector" type="fixed">
    <parent link="lifter_top_link"/>
    <child link="waist_link"/>
    <origin rpy="0 0 0 " xyz="0.0 0.0 0.0"/>
  </joint>
  <!-- ============================   aero(typeE_wheels)   ============================ -->
  <link name="base_link"/>
  <link name="wheel_base_link">
    <visual>
      <origin rpy="0 -0 0" xyz="0.0 0.0 0.0"/>
      <geometry>
        <mesh filename="package://aero_description/meshes/typeE_wheel/wheels_base.dae" scale="1 1 1"/>
      </geometry>
    </visual>
    <collision>
      <!--origin xyz="0.0 0.0 0.0" rpy="0 -0 0"/>
        <geometry>
          <mesh filename="package://aero_description/meshes/typeE_wheel/wheels_base.dae" scale="1 1 1" />
        </geometry-->
      <origin rpy="0 -0 0" xyz="0.018 0.0 0.0375"/>
      <geometry>
        <box size="0.72 0.52 0.149"/>
      </geometry>
    </collision>
    <inertial>
      <mass value="70"/>
      <origin rpy="0 -0 0.0" xyz="0 0 0.04"/>
      <inertia ixx="0.528" ixy="0" ixz="0" iyy="2.02" iyz="0" izz="2.35"/>
    </inertial>
  </link>
  <gazebo reference="wheel_base_link">
    <mu1>0.9</mu1>
    <mu2>0.9</mu2>
  </gazebo>
  <link name="wheels_top_link">
    <visual>
      <origin rpy="0 -0 0" xyz="0.0 0.0 0.0"/>
      <geometry>
        <mesh filename="package://aero_description/meshes/typeE_wheel/wheels_top.dae" scale="1 1 1"/>
      </geometry>
    </visual>
    <!-- no collision geometry -->
    <inertial>
      <mass value="1"/>
      <origin rpy="0 -0 0" xyz="0 0 0"/>
      <inertia ixx="0.528" ixy="0" ixz="0" iyy="2.02" iyz="0" izz="2.35"/>
    </inertial>
  </link>
  <gazebo reference="wheels_top_link">
    <mu1>0.9</mu1>
    <mu2>0.9</mu2>
  </gazebo>
  <link name="wheels_front_left_mecanum">
    <visual>
      <origin rpy="-1.57079632679 0 0" xyz="0.0 0.0 0.0"/>
      <geometry>
        <mesh filename="package://aero_description/meshes/typeE_wheel/wheels_mecanum.dae" scale="1 1 1"/>
      </geometry>
    </visual>
    <collision>
      <origin rpy="-1.57079632679 0 0" xyz="0.0 0.0 0.0"/>
      <geometry>
        <!--cylinder length="0.046" radius="0.076" /-->
        <box size="0.152 0.152 0.046"/>
      </geometry>
    </collision>
    <inertial>
      <mass value="1"/>
      <origin rpy="0 -0 0" xyz="0 0 0"/>
      <inertia ixx="0.528" ixy="0" ixz="0" iyy="2.02" iyz="0" izz="2.35"/>
    </inertial>
  </link>
  <gazebo reference="wheels_front_left_mecanum">
    <mu1>0.25</mu1>
    <mu2>0.25</mu2>
  </gazebo>
  <link name="wheels_front_right_mecanum">
    <visual>
      <origin rpy="-1.57079632679 0 0" xyz="0.0 0.0 0.0"/>
      <geometry>
        <mesh filename="package://aero_description/meshes/typeE_wheel/wheels_mecanum.dae" scale="1 1 1"/>
      </geometry>
    </visual>
    <collision>
      <origin rpy="-1.57079632679 0 0" xyz="0.0 0.0 0.0"/>
      <geometry>
        <!--cylinder length="0.046" radius="0.076" /-->
        <box size="0.152 0.152 0.046"/>
      </geometry>
    </collision>
    <inertial>
      <mass value="1"/>
      <origin rpy="0 -0 0" xyz="0 0 0"/>
      <inertia ixx="0.528" ixy="0" ixz="0" iyy="2.02" iyz="0" izz="2.35"/>
    </inertial>
  </link>
  <gazebo reference="wheels_front_left_mecanum">
    <mu1>0.25</mu1>
    <mu2>0.25</mu2>
  </gazebo>
  <link name="wheels_rear_left_mecanum">
    <visual>
      <origin rpy="-1.57079632679 0 0" xyz="0.0 0.0 0.0"/>
      <geometry>
        <mesh filename="package://aero_description/meshes/typeE_wheel/wheels_mecanum.dae" scale="1 1 1"/>
      </geometry>
    </visual>
    <collision>
      <origin rpy="-1.57079632679 0 0" xyz="0.0 0.0 0.0"/>
      <geometry>
        <!--cylinder length="0.046" radius="0.076" /-->
        <box size="0.152 0.152 0.046"/>
      </geometry>
    </collision>
    <inertial>
      <mass value="1"/>
      <origin rpy="0 -0 0" xyz="0 0 0"/>
      <inertia ixx="0.528" ixy="0" ixz="0" iyy="2.02" iyz="0" izz="2.35"/>
    </inertial>
  </link>
  <gazebo reference="wheels_rear_left_mecanum">
    <mu1>0.25</mu1>
    <mu2>0.25</mu2>
  </gazebo>
  <link name="wheels_rear_right_mecanum">
    <visual>
      <origin rpy="-1.57079632679 0 0" xyz="0.0 0.0 0.0"/>
      <geometry>
        <mesh filename="package://aero_description/meshes/typeE_wheel/wheels_mecanum.dae" scale="1 1 1"/>
      </geometry>
    </visual>
    <collision>
      <origin rpy="-1.57079632679 0 0" xyz="0.0 0.0 0.0"/>
      <geometry>
        <!--cylinder length="0.046" radius="0.076" /-->
        <box size="0.152 0.152 0.046"/>
      </geometry>
    </collision>
    <inertial>
      <mass value="1"/>
      <origin rpy="0 -0 0" xyz="0 0 0"/>
      <inertia ixx="0.528" ixy="0" ixz="0" iyy="2.02" iyz="0" izz="2.35"/>
    </inertial>
  </link>
  <gazebo reference="wheels_rear_right_mecanum">
    <mu1>0.25</mu1>
    <mu2>0.25</mu2>
  </gazebo>
  <link name="wheels_base_laser_link">
    <visual>
      <origin rpy="0 0 0" xyz="0.0 0.0 0.0"/>
      <geometry>
        <mesh filename="package://aero_description/meshes/typeE_wheel/wheels_urg.dae" scale="1 1 1"/>
      </geometry>
    </visual>
    <collision>
      <origin rpy="0 -0 0" xyz="0.0 0.0 -0.0124"/>
      <geometry>
        <box size="0.08 0.1 0.07"/>
      </geometry>
    </collision>
    <inertial>
      <mass value="0.2"/>
      <origin rpy="0 -0 0" xyz="0 0 0"/>
      <inertia ixx="0.0528" ixy="0" ixz="0" iyy="0.0202" iyz="0" izz="0.0235"/>
    </inertial>
  </link>
  <gazebo reference="wheels_base_laser_link">
    <mu1>0.9</mu1>
    <mu2>0.9</mu2>
  </gazebo>
  <joint name="base_link_to_wheel_base_link_connector" type="fixed">
    <parent link="base_link"/>
    <child link="wheel_base_link"/>
    <origin rpy="0 0 0" xyz="0.0 0.0 0.075"/>
  </joint>
  <joint name="wheels_body_to_top_connector" type="fixed">
    <parent link="wheel_base_link"/>
    <child link="wheels_top_link"/>
    <origin rpy="0 0 0 " xyz="0.0 0.0 0.115"/>
  </joint>
  <joint name="wheels_body_to_front_left_mecanum_connector" type="fixed">
    <parent link="wheel_base_link"/>
    <child link="wheels_front_left_mecanum"/>
    <origin rpy="0 0 0" xyz="0.2265 0.19485 0"/>
  </joint>
  <joint name="wheels_body_to_front_right_mecanum_connector" type="fixed">
    <parent link="wheel_base_link"/>
    <child link="wheels_front_right_mecanum"/>
    <origin rpy="0 0 0" xyz="0.2265 -0.19485 0"/>
  </joint>
  <joint name="wheels_body_to_rear_left_mecanum_connector" type="fixed">
    <parent link="wheel_base_link"/>
    <child link="wheels_rear_left_mecanum"/>
    <origin rpy="0 0 0" xyz="-0.2265 0.19485 0"/>
  </joint>
  <joint name="wheels_body_to_rear_right_mecanum_connector" type="fixed">
    <parent link="wheel_base_link"/>
    <child link="wheels_rear_right_mecanum"/>
    <origin rpy="0 0 0" xyz="-0.2265 -0.19485 0"/>
  </joint>
  <joint name="wheels_body_to_base_laser_connector" type="fixed">
    <parent link="wheel_base_link"/>
    <child link="wheels_base_laser_link"/>
    <origin rpy="0 0 0" xyz="0.29 0 0.1324"/>
  </joint>
  <joint name="wheel_lifter_connector" type="fixed">
    <parent link="wheels_top_link"/>
    <child link="lifter_base_link"/>
    <origin rpy="0 0 0 " xyz="0.0 0.0 0.005"/>
  </joint>
  <!-- ============================   aero(typeC_lifter)   ============================ -->
  <link name="lifter_base_link">
    <visual>
      <origin rpy="0 -0 0" xyz="0 0 0"/>
      <geometry>
        <mesh filename="package://aero_description/meshes/typeC_lifter/lifter_base.dae" scale="1 1 1"/>
      </geometry>
    </visual>
    <collision>
      <origin rpy="0 -0 0" xyz="0 0 0"/>
      <geometry>
        <mesh filename="package://aero_description/meshes/typeC_lifter/lifter_base.dae" scale="1 1 1"/>
      </geometry>
    </collision>
    <inertial>
      <mass value="7.64604"/>
      <origin rpy="0 -0 0" xyz="-0.012819 -0.002679 0.007207"/>
      <inertia ixx="0.0658136" ixy="-0.000159462" ixz="0.010103" iyy="0.0504268" iyz="0.000173435" izz="0.0889772"/>
    </inertial>
  </link>
  <gazebo reference="lifter_base_link">
    <mu1>0.9</mu1>
    <mu2>0.9</mu2>
  </gazebo>
  <link name="leg_shank_link">
    <visual>
      <origin rpy="3.1415 -0 0" xyz="0.0 0.0 0"/>
      <geometry>
        <mesh filename="package://aero_description/meshes/typeC_lifter/lifter_bone.dae" scale="1 1 1"/>
      </geometry>
    </visual>
    <collision>
      <origin rpy="3.1415 -0 0" xyz="0.0 0.0 0"/>
      <geometry>
        <mesh filename="package://aero_description/meshes/typeC_lifter/lifter_bone.dae" scale="1 1 1"/>
      </geometry>
    </collision>
    <inertial>
      <mass value="2.06679"/>
      <!--origin xyz="0.081713 0.000812 -0.146934" rpy="0 -0 0"/-->
      <origin rpy="0 -0 0" xyz="0.051713 0.0 0.146934"/>
      <!--inertia ixx="0.0408818" ixy="-9.39301e-06" ixz="-0.000750165" iyy="0.0403969" iyz="-0.000120419" izz="0.00260982"/-->
      <inertia ixx="0.06" ixy="0.0" ixz="0.0" iyy="0.1" iyz="0.0" izz="0.06"/>
    </inertial>
  </link>
  <gazebo reference="leg_shank_link">
    <mu1>0.9</mu1>
    <mu2>0.9</mu2>
  </gazebo>
  <link name="leg_knee_link">
    <visual>
      <origin rpy="3.1415 -0 0" xyz="0.0 0.0 0"/>
      <geometry>
        <mesh filename="package://aero_description/meshes/typeC_lifter/lifter_knee.dae" scale="1 1 1"/>
      </geometry>
    </visual>
    <collision>
      <origin rpy="3.1415 -0 0" xyz="0.0 0.0 0"/>
      <geometry>
        <mesh filename="package://aero_description/meshes/typeC_lifter/lifter_knee.dae" scale="1 1 1"/>
      </geometry>
    </collision>
    <inertial>
      <mass value="2.06679"/>
      <!--origin xyz="0.081713 0.000812 -0.146934" rpy="0 -0 0"/-->
      <origin rpy="0 -0 0" xyz="-0.031713 0.0 0.046934"/>
      <!--inertia ixx="0.0408818" ixy="-9.39301e-06" ixz="-0.000750165" iyy="0.0403969" iyz="-0.000120419" izz="0.00260982"/-->
      <inertia ixx="0.06" ixy="0.0" ixz="0.0" iyy="0.1" iyz="0.0" izz="0.06"/>
    </inertial>
  </link>
  <gazebo reference="leg_knee_link">
    <mu1>0.9</mu1>
    <mu2>0.9</mu2>
  </gazebo>
  <link name="leg_thigh_link">
    <visual>
      <origin rpy="0 0 0" xyz="0 0 0.25"/>
      <geometry>
        <mesh filename="package://aero_description/meshes/typeC_lifter/lifter_bone.dae" scale="1 1 1"/>
      </geometry>
    </visual>
    <collision>
      <origin rpy="0 0 0" xyz="0 0 0.25"/>
      <geometry>
        <mesh filename="package://aero_description/meshes/typeC_lifter/lifter_bone.dae" scale="1 1 1"/>
      </geometry>
    </collision>
    <inertial>
      <mass value="2.62321"/>
      <!--origin xyz="0.0587169 0 -0.135292" rpy="0 -0 0"/-->
      <origin rpy="0 -0 0" xyz="-0.0587169 0 0.135292"/>
      <inertia ixx="0.0161595" ixy="-9.27234e-05" ixz="0.00262839" iyy="0.0166415" iyz="-0.00017447" izz="0.00477281"/>
    </inertial>
  </link>
  <gazebo reference="leg_thigh_link">
    <mu1>0.9</mu1>
    <mu2>0.9</mu2>
  </gazebo>
  <link name="leg_base_link">
    <visual>
      <origin rpy="3.1415920 0 0" xyz="0 0 0.05"/>
      <geometry>
        <mesh filename="package://aero_description/meshes/typeC_lifter/lifter_base.dae" scale="1 1 1"/>
      </geometry>
    </visual>
    <collision>
      <origin rpy="3.1415920 0 0" xyz="0 0 0.05"/>
      <geometry>
        <mesh filename="package://aero_description/meshes/typeC_lifter/lifter_base.dae" scale="1 1 1"/>
      </geometry>
    </collision>
    <inertial>
      <mass value="7.64604"/>
      <origin rpy="0 -0 0" xyz="-0.012819 -0.002679 0.007207"/>
      <inertia ixx="0.0658136" ixy="-0.000159462" ixz="0.010103" iyy="0.0504268" iyz="0.000173435" izz="0.0889772"/>
    </inertial>
  </link>
  <gazebo reference="leg_base_link">
    <mu1>0.9</mu1>
    <mu2>0.9</mu2>
  </gazebo>
  <link name="lifter_top_link">
    <visual>
      <origin rpy="0 -0 0" xyz="0 0 0"/>
      <geometry>
        <mesh filename="package://aero_description/meshes/typeC_lifter/lifter_top.dae" scale="1 1 1"/>
      </geometry>
    </visual>
    <collision>
      <origin rpy="0 -0 0" xyz="0 0 0"/>
      <geometry>
        <mesh filename="package://aero_description/meshes/typeC_lifter/lifter_top.dae" scale="1 1 1"/>
      </geometry>
    </collision>
    <inertial>
      <mass value="1.0"/>
      <origin rpy="0 0 0" xyz="0.0 0.0 0.0"/>
      <inertia ixx="0.03" ixy="0.0" ixz="0.0" iyy="0.03" iyz="0.0" izz="0.04"/>
    </inertial>
  </link>
  <gazebo reference="lifter_top_link">
    <mu1>0.9</mu1>
    <mu2>0.9</mu2>
  </gazebo>
  <joint name="lifter_top_connector" type="fixed">
    <parent link="leg_base_link"/>
    <child link="lifter_top_link"/>
    <origin rpy="0 0 0" xyz="0 0 0.055"/>
  </joint>
  <joint name="knee_joint_mimic" type="revolute">
    <parent link="leg_thigh_link"/>
    <child link="leg_base_link"/>
    <origin rpy="0 0 0" xyz="0 0 0.25"/>
    <axis xyz="0 -1 0"/>
    <mimic joint="knee_joint" multiplier="-1" offset="0"/>
    <limit effort="10000" lower="0" upper="1.5707" velocity="0.5"/>
    <!-- just invert of knee_joint -->
  </joint>
  <joint name="knee_joint" type="revolute">
    <!-- rename "knee_joint_thigh_dummy" -->
    <parent link="leg_knee_link"/>
    <child link="leg_thigh_link"/>
    <origin rpy="0 0 0" xyz="0 0 0.12"/>
    <axis xyz="0 -1 0"/>
    <limit effort="10000" lower="-1.5707" upper="0" velocity="0.5"/>
  </joint>
  <transmission name="knee_joint_trans">
    <type>transmission_interface/SimpleTransmission</type>
    <joint name="knee_joint">
      <!-- dupricated in kinetic -->
      <!--hardwareInterface>hardware_interface/EffortJointInterface</hardwareInterface-->
      <!--hardwareInterface>EffortJointInterface</hardwareInterface-->
      <hardwareInterface>VelocityJointInterface</hardwareInterface>
    </joint>
    <actuator name="knee_joint_motor">
      <!-- dupricated in kinetic -->
      <!--hardwareInterface>hardware_interface/EffortJointInterface</hardwareInterface-->
      <!--hardwareInterface>EffortJointInterface</hardwareInterface-->
      <hardwareInterface>VelocityJointInterface</hardwareInterface>
      <mechanicalReduction>1</mechanicalReduction>
    </actuator>
  </transmission>
  <gazebo reference="knee_joint">
    <implicitSpringDamper>0</implicitSpringDamper>
  </gazebo>
  <joint name="ankle_joint" type="revolute">
    <parent link="lifter_base_link"/>
    <child link="leg_shank_link"/>
    <origin rpy="0 0 0" xyz="0 0 0.05"/>
    <axis xyz="0 -1 0"/>
    <limit effort="10000" lower="0" upper="1.5707" velocity="0.5"/>
    <dynamics damping="0.2" friction="0"/>
  </joint>
  <transmission name="ankle_joint_trans">
    <type>transmission_interface/SimpleTransmission</type>
    <joint name="ankle_joint">
      <!-- dupricated in kinetic -->
      <!--hardwareInterface>hardware_interface/EffortJointInterface</hardwareInterface-->
      <!--hardwareInterface>EffortJointInterface</hardwareInterface-->
      <hardwareInterface>VelocityJointInterface</hardwareInterface>
    </joint>
    <actuator name="ankle_joint_motor">
      <!-- dupricated in kinetic -->
      <!--hardwareInterface>hardware_interface/EffortJointInterface</hardwareInterface-->
      <!--hardwareInterface>EffortJointInterface</hardwareInterface-->
      <hardwareInterface>VelocityJointInterface</hardwareInterface>
      <mechanicalReduction>1</mechanicalReduction>
    </actuator>
  </transmission>
  <gazebo reference="ankle_joint">
    <implicitSpringDamper>0</implicitSpringDamper>
  </gazebo>
  <!--- mimic joints -->
  <!-- requried -->
  <joint name="ankle_joint_mimic" type="revolute">
    <parent link="leg_shank_link"/>
    <child link="leg_knee_link"/>
    <origin rpy="0 0 0" xyz="0 0 0.25"/>
    <axis xyz="0 -1 0"/>
    <mimic joint="ankle_joint" multiplier="-1" offset="0"/>
    <limit effort="10000" lower="-1.5707" upper="0" velocity="0.5"/>
    <!-- just invert of ankle_joint -->
  </joint>
  <!-- redundant -->
  <link name="leg_shank_link_dummy">
    <visual>
      <geometry>
        <mesh filename="package://aero_description/meshes/typeC_lifter/lifter_bone_dummy.dae" scale="1 1 1"/>
      </geometry>
      <origin rpy="0 0 0" xyz="0 0 0.25"/>
    </visual>
    <inertial>
      <!-- for gazebo visualization -->
      <mass value="0.4"/>
      <origin rpy="0 0 0" xyz="-0.04 0.0 0.14"/>
      <inertia ixx="0.001" ixy="0" ixz="0" iyy="0.001" iyz="0" izz="0.001"/>
    </inertial>
  </link>
  <link name="leg_thigh_link_dummy">
    <visual>
      <geometry>
        <mesh filename="package://aero_description/meshes/typeC_lifter/lifter_bone_dummy.dae" scale="1 1 1"/>
      </geometry>
      <origin rpy="0 0 0" xyz="0 0 0.25"/>
    </visual>
    <inertial>
      <!-- for gazebo visualization -->
      <mass value="0.4"/>
      <origin rpy="0 0 0" xyz="-0.04 0.0 0.14"/>
      <inertia ixx="0.001" ixy="0" ixz="0" iyy="0.001" iyz="0" izz="0.001"/>
    </inertial>
  </link>
  <joint name="ankle_joint_dummy" type="continuous">
    <parent link="lifter_base_link"/>
    <child link="leg_shank_link_dummy"/>
    <origin rpy="0 0 0" xyz="0.03182 0 0.08182"/>
    <axis xyz="0 -1 0"/>
    <mimic joint="ankle_joint" multiplier="1" offset="0"/>
  </joint>
  <joint name="knee_joint_dummy" type="continuous">
    <parent link="leg_knee_link"/>
    <child link="leg_thigh_link_dummy"/>
    <origin rpy="0 0 0" xyz="0.03182 0 0.08818"/>
    <axis xyz="0 1 0"/>
    <mimic joint="knee_joint" multiplier="-1" offset="0"/>
  </joint>
  <!-- gazebo settings -->
  <!-- camera -->
  <link name="camera_frame"/>
  <link name="camera_optical_frame"/>
  <joint name="camera_setting" type="fixed">
    <parent link="head_link"/>
    <child link="camera_frame"/>
    <origin rpy="0 0.15 0" xyz="0 0.035 0.09"/>
  </joint>
  <joint name="camera_optical" type="fixed">
    <parent link="camera_frame"/>
    <child link="camera_optical_frame"/>
    <origin rpy="-1.570796326795 0 -1.570796326795" xyz="0 0 0"/>
  </joint>
  <!-- camera -->
  <gazebo reference="camera_frame">
    <sensor name="camera1" type="camera">
      <update_rate>15.0</update_rate>
      <camera name="head">
        <horizontal_fov>1.7</horizontal_fov>
        <!-- -->
        <image>
          <width>800</width>
          <height>800</height>
          <format>R8G8B8</format>
        </image>
        <clip>
          <near>0.15</near>
          <far>300</far>
        </clip>
        <noise>
          <type>gaussian</type>
          <!--Noise is sampled independently per pixel on each frame.
                 That pixel's noise value is added to each of its color
                 channels, which at that point lie in the range [0,1]. -->
          <mean>0.0</mean>
          <stddev>0.007</stddev>
        </noise>
      </camera>
      <plugin filename="libgazebo_ros_camera.so" name="camera_controller">
        <alwaysOn>true</alwaysOn>
        <updateRate>0.0</updateRate>
        <cameraName>camera</cameraName>
        <imageTopicName>image_raw</imageTopicName>
        <cameraInfoTopicName>camera_info</cameraInfoTopicName>
        <frameName>camera_optical_frame</frameName>
        <!--setting hackBaseline to anything but 0.0 will cause a misalignment
               between the gazebo sensor image and the frame it is supposed to
               be attached to-->
        <hackBaseline>0.0</hackBaseline>
        <distortionK1>0.0</distortionK1>
        <distortionK2>0.0</distortionK2>
        <distortionK3>0.0</distortionK3>
        <distortionT1>0.0</distortionT1>
        <distortionT2>0.0</distortionT2>
        <CxPrime>0</CxPrime>
        <Cx>0.0</Cx>
        <Cy>0.0</Cy>
        <focalLength>0.0</focalLength>
      </plugin>
    </sensor>
  </gazebo>
  <!-- hokuyo -->
  <gazebo reference="wheels_base_laser_link">
    <sensor name="head_hokuyo_sensor" type="ray">
      <pose>0 0 0 0 0 0</pose>
      <visualize>false</visualize>
      <update_rate>40</update_rate>
      <ray>
        <scan>
          <horizontal>
            <samples>1000</samples>
            <resolution>1</resolution>
            <min_angle>-2.35619449</min_angle>
            <max_angle>2.35619449</max_angle>
          </horizontal>
        </scan>
        <range>
          <min>0.5</min>
          <max>30.0</max>
          <resolution>0.01</resolution>
        </range>
        <noise>
          <type>gaussian</type>
          <!--
                 Noise parameters based on published spec for Hokuyo laser
                 achieving "+-30mm" accuracy at range < 10m.  A mean of 0.0m and
                 stddev of 0.01m will put 99.7% of samples within 0.03m of the true
                 reading.
                 -->
          <mean>0.0</mean>
          <stddev>0.01</stddev>
        </noise>
      </ray>
      <plugin filename="libgazebo_ros_laser.so" name="gazebo_ros_head_hokuyo_controller">
        <topicName>scan</topicName>
        <frameName>wheels_base_laser_link</frameName>
      </plugin>
    </sensor>
  </gazebo>
  <gazebo>
    <plugin filename="libgazebo_ros_control.so" name="gazebo_ros_control">
      <robotNamespace>/</robotNamespace>
      <robotSimType>gazebo_ros_control/DefaultRobotHWSim</robotSimType>
    </plugin>
  </gazebo>
  <!-- Base control -->
  <gazebo>
    <!--plugin name="cmd_vel_controller" filename="libgazebo_ros_planar_force_move.so"-->
    <plugin filename="libgazebo_ros_planar_force_move.so" name="cmd_vel_controller">
      <commandTopic>cmd_vel</commandTopic>
      <odometryTopic>odom</odometryTopic>
      <odometryFrame>odom</odometryFrame>
      <odometryRate>40.0</odometryRate>
      <robotBaseFrame>base_link</robotBaseFrame>
      <useForceFeedback>true</useForceFeedback>
      <appliedForceLink>base_link</appliedForceLink>
      <forceGainX>24000</forceGainX>
      <forceGainY>24000</forceGainY>
      <forceGainRot>6000</forceGainRot>
    </plugin>
  </gazebo>
  <!-- mimic joints -->
  <gazebo>
    <plugin filename="libmimic_plugin.so" name="mimic_updater">
      <!-- lifter -->
      <mimic D="0" I="0" P="300" command_max="100" command_min="-100" i_max="5" i_min="-5" joint="knee_joint" multiplier="-1.0" offset="0.0" velocity="true">
        
       knee_joint_mimic
       
        <joint> knee_joint </joint>
        <offset> 0.0 </offset>
        <multiplier> -1.0 </multiplier>
        <P> 300 </P>
        <I> 0 </I>
        <D> 0 </D>
        <i_max>  5 </i_max>
        <i_min> -5 </i_min>
        <command_max>  100 </command_max>
        <command_min> -100 </command_min>
        <velocity> true </velocity>
      </mimic>
      <mimic D="0" I="0" P="300" command_max="100" command_min="-100" i_max="5" i_min="-5" joint="ankle_joint" multiplier="-1.0" offset="0.0" velocity="true">
        
       ankle_joint_mimic
       
        <joint> ankle_joint </joint>
        <offset> 0.0 </offset>
        <multiplier> -1.0 </multiplier>
        <P> 300 </P>
        <I> 0 </I>
        <D> 0 </D>
        <i_max>  5 </i_max>
        <i_min> -5 </i_min>
        <command_max>  100 </command_max>
        <command_min> -100 </command_min>
        <velocity> true </velocity>
      </mimic>
      <!-- lifter(dummy) -->
      <mimic D="1" I="0.0" P="1000" command_max="200" command_min="-200" i_max="0" i_min="0" joint="knee_joint" multiplier="-1.0" offset="0.0">
        
       knee_joint_dummy
       
        <joint> knee_joint </joint>
        <offset> 0.0 </offset>
        <multiplier> -1.0 </multiplier>
        <P> 1000 </P>
        <I> 0.0 </I>
        <D> 1 </D>
        <i_max>  0 </i_max>
        <i_min> -0 </i_min>
        <command_max>  200 </command_max>
        <command_min> -200 </command_min>
      </mimic>
      <mimic D="1" I="0.0" P="1000" command_max="200" command_min="-200" i_max="0" i_min="0" joint="ankle_joint" multiplier="1.0" offset="0.0">
        
       ankle_joint_dummy
       
        <joint> ankle_joint </joint>
        <offset> 0.0 </offset>
        <multiplier> 1.0 </multiplier>
        <P> 1000 </P>
        <I> 0.0 </I>
        <D> 1 </D>
        <i_max>  0 </i_max>
        <i_min> -0 </i_min>
        <command_max>  200 </command_max>
        <command_min> -200 </command_min>
      </mimic>
      <!-- lhand -->
      <mimic D="0.03" I="0.0" P="30" command_max="50" command_min="-50" i_max="0" i_min="0" joint="l_indexbase_joint" multiplier="-0.3" offset="-0.2">
        
       l_indexend_joint
       
        <joint> l_indexbase_joint </joint>
        <offset> -0.2 </offset>
        <multiplier> -0.3 </multiplier>
        <P> 30 </P>
        <I> 0.0 </I>
        <D> 0.03 </D>
        <i_max>  0 </i_max>
        <i_min> -0 </i_min>
        <command_max>  50 </command_max>
        <command_min> -50 </command_min>
      </mimic>
      <!-- rhand -->
      <mimic D="0.03" I="0.0" P="30" command_max="50" command_min="-50" i_max="0" i_min="0" joint="r_indexbase_joint" multiplier="-0.3" offset="0.2">
        
       r_indexend_joint
       
        <joint> r_indexbase_joint </joint>
        <offset> 0.2 </offset>
        <multiplier> -0.3 </multiplier>
        <P> 30 </P>
        <I> 0.0 </I>
        <D> 0.03 </D>
        <i_max>  0 </i_max>
        <i_min> -0 </i_min>
        <command_max>  50 </command_max>
        <command_min> -50 </command_min>
      </mimic>
    </plugin>
  </gazebo>
</robot>
