<?xml version="1.0" encoding="utf-8"?>
<!-- =================================================================================== -->
<!-- |    This document was autogenerated by xacro from dual_panda2.urdf.xacro         | -->
<!-- |    EDITING THIS FILE BY HAND IS NOT RECOMMENDED                                 | -->
<!-- =================================================================================== -->
<robot name="dual_panda">
  <joint name="rarm_joint_fixed_base" type="fixed">
    <parent link="fixed_base"/>
    <child link="rarm_link0"/>
    <origin rpy="0 0 0" xyz="-0.02 -0.34 0.0"/>
  </joint>
  <link name="rarm_link0">
    <visual>
      <geometry>
        <mesh filename="package://franka_description/meshes/visual/link0.dae"/>
      </geometry>
    </visual>
    <collision>
      <origin rpy="0 1.57079632679 0" xyz="-0.075 0 0.06"/>
      <geometry>
        <cylinder length="0.03" radius="0.09"/>
      </geometry>
    </collision>
    <collision>
      <origin rpy="0 0 0" xyz="-0.06 0 0.06"/>
      <geometry>
        <sphere radius="0.09"/>
      </geometry>
    </collision>
    <collision>
      <origin rpy="0 0 0" xyz="-0.09 0 0.06"/>
      <geometry>
        <sphere radius="0.09"/>
      </geometry>
    </collision>
  </link>
  <link name="rarm_link1">
    <visual>
      <geometry>
        <mesh filename="package://franka_description/meshes/visual/link1.dae"/>
      </geometry>
    </visual>
    <collision>
      <origin rpy="0 0 0" xyz="0 0 -0.1915"/>
      <geometry>
        <cylinder length="0.2830" radius="0.09"/>
      </geometry>
    </collision>
    <collision>
      <origin rpy="0 0 0" xyz="0 0 -0.333"/>
      <geometry>
        <sphere radius="0.09"/>
      </geometry>
    </collision>
    <collision>
      <origin rpy="0 0 0" xyz="0 0 -0.05"/>
      <geometry>
        <sphere radius="0.09"/>
      </geometry>
    </collision>
  </link>
  <joint name="rarm_joint1" type="revolute">
    <safety_controller k_position="100.0" k_velocity="40.0" soft_lower_limit="-2.8973" soft_upper_limit="2.8973"/>
    <origin rpy="0 0 0" xyz="0 0 0.333"/>
    <parent link="rarm_link0"/>
    <child link="rarm_link1"/>
    <axis xyz="0 0 1"/>
    <limit effort="87" lower="-2.8973" upper="2.8973" velocity="2.1750"/>
  </joint>
  <link name="rarm_link2">
    <visual>
      <geometry>
        <mesh filename="package://franka_description/meshes/visual/link2.dae"/>
      </geometry>
    </visual>
    <collision>
      <origin rpy="0 0 0" xyz="0 0 0"/>
      <geometry>
        <cylinder length="0.12" radius="0.09"/>
      </geometry>
    </collision>
    <collision>
      <origin rpy="0 0 0" xyz="0 0 -0.06"/>
      <geometry>
        <sphere radius="0.09"/>
      </geometry>
    </collision>
    <collision>
      <origin rpy="0 0 0" xyz="0 0 0.06"/>
      <geometry>
        <sphere radius="0.09"/>
      </geometry>
    </collision>
  </link>
  <joint name="rarm_joint2" type="revolute">
    <safety_controller k_position="100.0" k_velocity="40.0" soft_lower_limit="-1.7628" soft_upper_limit="1.7628"/>
    <origin rpy="-1.57079632679 0 0" xyz="0 0 0"/>
    <parent link="rarm_link1"/>
    <child link="rarm_link2"/>
    <axis xyz="0 0 1"/>
    <limit effort="87" lower="-1.7628" upper="1.7628" velocity="2.1750"/>
  </joint>
  <link name="rarm_link3">
    <visual>
      <geometry>
        <mesh filename="package://franka_description/meshes/visual/link3.dae"/>
      </geometry>
    </visual>
    <collision>
      <origin rpy="0 0 0" xyz="0 0 -0.145"/>
      <geometry>
        <cylinder length="0.15" radius="0.09"/>
      </geometry>
    </collision>
    <collision>
      <origin rpy="0 0 0" xyz="0 0 -0.22"/>
      <geometry>
        <sphere radius="0.09"/>
      </geometry>
    </collision>
    <collision>
      <origin rpy="0 0 0" xyz="0 0 -0.07"/>
      <geometry>
        <sphere radius="0.09"/>
      </geometry>
    </collision>
  </link>
  <joint name="rarm_joint3" type="revolute">
    <safety_controller k_position="100.0" k_velocity="40.0" soft_lower_limit="-2.8973" soft_upper_limit="2.8973"/>
    <origin rpy="1.57079632679 0 0" xyz="0 -0.316 0"/>
    <parent link="rarm_link2"/>
    <child link="rarm_link3"/>
    <axis xyz="0 0 1"/>
    <limit effort="87" lower="-2.8973" upper="2.8973" velocity="2.1750"/>
  </joint>
  <link name="rarm_link4">
    <visual>
      <geometry>
        <mesh filename="package://franka_description/meshes/visual/link4.dae"/>
      </geometry>
    </visual>
    <collision>
      <origin rpy="0 0 0" xyz="0 0 0"/>
      <geometry>
        <cylinder length="0.12" radius="0.09"/>
      </geometry>
    </collision>
    <collision>
      <origin rpy="0 0 0" xyz="0 0 0.06"/>
      <geometry>
        <sphere radius="0.09"/>
      </geometry>
    </collision>
    <collision>
      <origin rpy="0 0 0" xyz="0 0 -0.06"/>
      <geometry>
        <sphere radius="0.09"/>
      </geometry>
    </collision>
  </link>
  <joint name="rarm_joint4" type="revolute">
    <safety_controller k_position="100.0" k_velocity="40.0" soft_lower_limit="-3.0718" soft_upper_limit="-0.0698"/>
    <origin rpy="1.57079632679 0 0" xyz="0.0825 0 0"/>
    <parent link="rarm_link3"/>
    <child link="rarm_link4"/>
    <axis xyz="0 0 1"/>
    <limit effort="87" lower="-3.0718" upper="-0.0698" velocity="2.1750"/>
  </joint>
  <link name="rarm_link5">
    <visual>
      <geometry>
        <mesh filename="package://franka_description/meshes/visual/link5.dae"/>
      </geometry>
    </visual>
    <collision>
      <origin rpy="0 0 0" xyz="0 0 -0.26"/>
      <geometry>
        <cylinder length="0.1" radius="0.09"/>
      </geometry>
    </collision>
    <collision>
      <origin rpy="0 0 0" xyz="0 0 -0.31"/>
      <geometry>
        <sphere radius="0.09"/>
      </geometry>
    </collision>
    <collision>
      <origin rpy="0 0 0" xyz="0 0 -0.21"/>
      <geometry>
        <sphere radius="0.09"/>
      </geometry>
    </collision>
    <collision>
      <origin rpy="0 0 0" xyz="0 0.08 -0.13"/>
      <geometry>
        <cylinder length="0.14" radius="0.055"/>
      </geometry>
    </collision>
    <collision>
      <origin rpy="0 0 0" xyz="0 0.08 -0.06"/>
      <geometry>
        <sphere radius="0.055"/>
      </geometry>
    </collision>
    <collision>
      <origin rpy="0 0 0" xyz="0 0.08 -0.20"/>
      <geometry>
        <sphere radius="0.055"/>
      </geometry>
    </collision>
  </link>
  <joint name="rarm_joint5" type="revolute">
    <safety_controller k_position="100.0" k_velocity="40.0" soft_lower_limit="-2.8973" soft_upper_limit="2.8973"/>
    <origin rpy="-1.57079632679 0 0" xyz="-0.0825 0.384 0"/>
    <parent link="rarm_link4"/>
    <child link="rarm_link5"/>
    <axis xyz="0 0 1"/>
    <limit effort="12" lower="-2.8973" upper="2.8973" velocity="2.6100"/>
  </joint>
  <link name="rarm_link6">
    <visual>
      <geometry>
        <mesh filename="package://franka_description/meshes/visual/link6.dae"/>
      </geometry>
    </visual>
    <collision>
      <origin rpy="0 0 0" xyz="0 0 -0.03"/>
      <geometry>
        <cylinder length="0.08" radius="0.08"/>
      </geometry>
    </collision>
    <collision>
      <origin rpy="0 0 0" xyz="0 0 0.01"/>
      <geometry>
        <sphere radius="0.08"/>
      </geometry>
    </collision>
    <collision>
      <origin rpy="0 0 0" xyz="0 0 -0.07"/>
      <geometry>
        <sphere radius="0.08"/>
      </geometry>
    </collision>
  </link>
  <joint name="rarm_joint6" type="revolute">
    <safety_controller k_position="100.0" k_velocity="40.0" soft_lower_limit="-0.0175" soft_upper_limit="3.7525"/>
    <origin rpy="1.57079632679 0 0" xyz="0 0 0"/>
    <parent link="rarm_link5"/>
    <child link="rarm_link6"/>
    <axis xyz="0 0 1"/>
    <limit effort="12" lower="-0.0175" upper="3.7525" velocity="2.6100"/>
  </joint>
  <link name="rarm_link7">
    <visual>
      <geometry>
        <mesh filename="package://franka_description/meshes/visual/link7.dae"/>
      </geometry>
    </visual>
    <collision>
      <origin rpy="0 0 0" xyz="0 0 0.01"/>
      <geometry>
        <cylinder length="0.14" radius="0.07"/>
      </geometry>
    </collision>
    <collision>
      <origin rpy="0 0 0" xyz="0 0 0.08"/>
      <geometry>
        <sphere radius="0.07"/>
      </geometry>
    </collision>
    <collision>
      <origin rpy="0 0 0" xyz="0 0 -0.06"/>
      <geometry>
        <sphere radius="0.07"/>
      </geometry>
    </collision>
  </link>
  <joint name="rarm_joint7" type="revolute">
    <safety_controller k_position="100.0" k_velocity="40.0" soft_lower_limit="-2.8973" soft_upper_limit="2.8973"/>
    <origin rpy="1.57079632679 0 0" xyz="0.088 0 0"/>
    <parent link="rarm_link6"/>
    <child link="rarm_link7"/>
    <axis xyz="0 0 1"/>
    <limit effort="12" lower="-2.8973" upper="2.8973" velocity="2.6100"/>
  </joint>
  <link name="rarm_link8">
    <collision>
      <origin rpy="3.14159265359 1.57079632679 1.57079632679" xyz="0.0424 0.0424 -0.0250"/>
      <geometry>
        <cylinder length="0.01" radius="0.06"/>
      </geometry>
    </collision>
    <collision>
      <origin rpy="0 0 0" xyz="0.0424 0.0424 -0.02"/>
      <geometry>
        <sphere radius="0.06"/>
      </geometry>
    </collision>
    <collision>
      <origin rpy="0 0 0" xyz="0.0424 0.0424 -0.03"/>
      <geometry>
        <sphere radius="0.06"/>
      </geometry>
    </collision>
  </link>
  <joint name="rarm_joint8" type="fixed">
    <origin rpy="0 0 0" xyz="0 0 0.107"/>
    <parent link="rarm_link7"/>
    <child link="rarm_link8"/>
  </joint>
  <joint name="rarm_hand_joint" type="fixed">
    <parent link="rarm_link8"/>
    <child link="rarm_hand"/>
    <origin rpy="0 0 -0.785398163397" xyz="0 0 0"/>
  </joint>
  <link name="rarm_hand">
    <visual>
      <geometry>
        <mesh filename="package://franka_description/meshes/visual/hand.dae"/>
      </geometry>
    </visual>
    <collision>
      <origin rpy="0 1.57079632679 1.57079632679" xyz="0 0 0.04"/>
      <geometry>
        <cylinder length="0.1" radius="0.07"/>
      </geometry>
    </collision>
    <collision>
      <origin rpy="0 0 0" xyz="0 -0.05 0.04"/>
      <geometry>
        <sphere radius="0.07"/>
      </geometry>
    </collision>
    <collision>
      <origin rpy="0 0 0" xyz="0 0.05 0.04"/>
      <geometry>
        <sphere radius="0.07"/>
      </geometry>
    </collision>
    <collision>
      <origin rpy="0 1.57079632679 1.57079632679" xyz="0 0 0.1"/>
      <geometry>
        <cylinder length="0.1" radius="0.05"/>
      </geometry>
    </collision>
    <collision>
      <origin rpy="0 0 0" xyz="0 -0.05 0.1"/>
      <geometry>
        <sphere radius="0.05"/>
      </geometry>
    </collision>
    <collision>
      <origin rpy="0 0 0" xyz="0 0.05 0.1"/>
      <geometry>
        <sphere radius="0.05"/>
      </geometry>
    </collision>
  </link>
  <link name="rarm_leftfinger">
    <visual>
      <geometry>
        <mesh filename="package://franka_description/meshes/visual/finger.dae"/>
      </geometry>
    </visual>
  </link>
  <link name="rarm_rightfinger">
    <visual>
      <origin rpy="0 0 3.14159265359" xyz="0 0 0"/>
      <geometry>
        <mesh filename="package://franka_description/meshes/visual/finger.dae"/>
      </geometry>
    </visual>
  </link>
  <joint name="rarm_finger_joint1" type="prismatic">
    <parent link="rarm_hand"/>
    <child link="rarm_leftfinger"/>
    <origin rpy="0 0 0" xyz="0 0 0.0584"/>
    <axis xyz="0 1 0"/>
    <limit effort="20" lower="0.0" upper="0.04" velocity="0.2"/>
  </joint>
  <joint name="rarm_finger_joint2" type="prismatic">
    <parent link="rarm_hand"/>
    <child link="rarm_rightfinger"/>
    <origin rpy="0 0 0" xyz="0 0 0.0584"/>
    <axis xyz="0 -1 0"/>
    <limit effort="20" lower="0.0" upper="0.04" velocity="0.2"/>
    <mimic joint="rarm_finger_joint1"/>
  </joint>
  <joint name="larm_joint_fixed_base" type="fixed">
    <parent link="fixed_base"/>
    <child link="larm_link0"/>
    <origin rpy="0 0 0" xyz="-0.02  0.34 0.0"/>
  </joint>
  <link name="larm_link0">
    <visual>
      <geometry>
        <mesh filename="package://franka_description/meshes/visual/link0.dae"/>
      </geometry>
    </visual>
    <collision>
      <origin rpy="0 1.57079632679 0" xyz="-0.075 0 0.06"/>
      <geometry>
        <cylinder length="0.03" radius="0.09"/>
      </geometry>
    </collision>
    <collision>
      <origin rpy="0 0 0" xyz="-0.06 0 0.06"/>
      <geometry>
        <sphere radius="0.09"/>
      </geometry>
    </collision>
    <collision>
      <origin rpy="0 0 0" xyz="-0.09 0 0.06"/>
      <geometry>
        <sphere radius="0.09"/>
      </geometry>
    </collision>
  </link>
  <link name="larm_link1">
    <visual>
      <geometry>
        <mesh filename="package://franka_description/meshes/visual/link1.dae"/>
      </geometry>
    </visual>
    <collision>
      <origin rpy="0 0 0" xyz="0 0 -0.1915"/>
      <geometry>
        <cylinder length="0.2830" radius="0.09"/>
      </geometry>
    </collision>
    <collision>
      <origin rpy="0 0 0" xyz="0 0 -0.333"/>
      <geometry>
        <sphere radius="0.09"/>
      </geometry>
    </collision>
    <collision>
      <origin rpy="0 0 0" xyz="0 0 -0.05"/>
      <geometry>
        <sphere radius="0.09"/>
      </geometry>
    </collision>
  </link>
  <joint name="larm_joint1" type="revolute">
    <safety_controller k_position="100.0" k_velocity="40.0" soft_lower_limit="-2.8973" soft_upper_limit="2.8973"/>
    <origin rpy="0 0 0" xyz="0 0 0.333"/>
    <parent link="larm_link0"/>
    <child link="larm_link1"/>
    <axis xyz="0 0 1"/>
    <limit effort="87" lower="-2.8973" upper="2.8973" velocity="2.1750"/>
  </joint>
  <link name="larm_link2">
    <visual>
      <geometry>
        <mesh filename="package://franka_description/meshes/visual/link2.dae"/>
      </geometry>
    </visual>
    <collision>
      <origin rpy="0 0 0" xyz="0 0 0"/>
      <geometry>
        <cylinder length="0.12" radius="0.09"/>
      </geometry>
    </collision>
    <collision>
      <origin rpy="0 0 0" xyz="0 0 -0.06"/>
      <geometry>
        <sphere radius="0.09"/>
      </geometry>
    </collision>
    <collision>
      <origin rpy="0 0 0" xyz="0 0 0.06"/>
      <geometry>
        <sphere radius="0.09"/>
      </geometry>
    </collision>
  </link>
  <joint name="larm_joint2" type="revolute">
    <safety_controller k_position="100.0" k_velocity="40.0" soft_lower_limit="-1.7628" soft_upper_limit="1.7628"/>
    <origin rpy="-1.57079632679 0 0" xyz="0 0 0"/>
    <parent link="larm_link1"/>
    <child link="larm_link2"/>
    <axis xyz="0 0 1"/>
    <limit effort="87" lower="-1.7628" upper="1.7628" velocity="2.1750"/>
  </joint>
  <link name="larm_link3">
    <visual>
      <geometry>
        <mesh filename="package://franka_description/meshes/visual/link3.dae"/>
      </geometry>
    </visual>
    <collision>
      <origin rpy="0 0 0" xyz="0 0 -0.145"/>
      <geometry>
        <cylinder length="0.15" radius="0.09"/>
      </geometry>
    </collision>
    <collision>
      <origin rpy="0 0 0" xyz="0 0 -0.22"/>
      <geometry>
        <sphere radius="0.09"/>
      </geometry>
    </collision>
    <collision>
      <origin rpy="0 0 0" xyz="0 0 -0.07"/>
      <geometry>
        <sphere radius="0.09"/>
      </geometry>
    </collision>
  </link>
  <joint name="larm_joint3" type="revolute">
    <safety_controller k_position="100.0" k_velocity="40.0" soft_lower_limit="-2.8973" soft_upper_limit="2.8973"/>
    <origin rpy="1.57079632679 0 0" xyz="0 -0.316 0"/>
    <parent link="larm_link2"/>
    <child link="larm_link3"/>
    <axis xyz="0 0 1"/>
    <limit effort="87" lower="-2.8973" upper="2.8973" velocity="2.1750"/>
  </joint>
  <link name="larm_link4">
    <visual>
      <geometry>
        <mesh filename="package://franka_description/meshes/visual/link4.dae"/>
      </geometry>
    </visual>
    <collision>
      <origin rpy="0 0 0" xyz="0 0 0"/>
      <geometry>
        <cylinder length="0.12" radius="0.09"/>
      </geometry>
    </collision>
    <collision>
      <origin rpy="0 0 0" xyz="0 0 0.06"/>
      <geometry>
        <sphere radius="0.09"/>
      </geometry>
    </collision>
    <collision>
      <origin rpy="0 0 0" xyz="0 0 -0.06"/>
      <geometry>
        <sphere radius="0.09"/>
      </geometry>
    </collision>
  </link>
  <joint name="larm_joint4" type="revolute">
    <safety_controller k_position="100.0" k_velocity="40.0" soft_lower_limit="-3.0718" soft_upper_limit="-0.0698"/>
    <origin rpy="1.57079632679 0 0" xyz="0.0825 0 0"/>
    <parent link="larm_link3"/>
    <child link="larm_link4"/>
    <axis xyz="0 0 1"/>
    <limit effort="87" lower="-3.0718" upper="-0.0698" velocity="2.1750"/>
  </joint>
  <link name="larm_link5">
    <visual>
      <geometry>
        <mesh filename="package://franka_description/meshes/visual/link5.dae"/>
      </geometry>
    </visual>
    <collision>
      <origin rpy="0 0 0" xyz="0 0 -0.26"/>
      <geometry>
        <cylinder length="0.1" radius="0.09"/>
      </geometry>
    </collision>
    <collision>
      <origin rpy="0 0 0" xyz="0 0 -0.31"/>
      <geometry>
        <sphere radius="0.09"/>
      </geometry>
    </collision>
    <collision>
      <origin rpy="0 0 0" xyz="0 0 -0.21"/>
      <geometry>
        <sphere radius="0.09"/>
      </geometry>
    </collision>
    <collision>
      <origin rpy="0 0 0" xyz="0 0.08 -0.13"/>
      <geometry>
        <cylinder length="0.14" radius="0.055"/>
      </geometry>
    </collision>
    <collision>
      <origin rpy="0 0 0" xyz="0 0.08 -0.06"/>
      <geometry>
        <sphere radius="0.055"/>
      </geometry>
    </collision>
    <collision>
      <origin rpy="0 0 0" xyz="0 0.08 -0.20"/>
      <geometry>
        <sphere radius="0.055"/>
      </geometry>
    </collision>
  </link>
  <joint name="larm_joint5" type="revolute">
    <safety_controller k_position="100.0" k_velocity="40.0" soft_lower_limit="-2.8973" soft_upper_limit="2.8973"/>
    <origin rpy="-1.57079632679 0 0" xyz="-0.0825 0.384 0"/>
    <parent link="larm_link4"/>
    <child link="larm_link5"/>
    <axis xyz="0 0 1"/>
    <limit effort="12" lower="-2.8973" upper="2.8973" velocity="2.6100"/>
  </joint>
  <link name="larm_link6">
    <visual>
      <geometry>
        <mesh filename="package://franka_description/meshes/visual/link6.dae"/>
      </geometry>
    </visual>
    <collision>
      <origin rpy="0 0 0" xyz="0 0 -0.03"/>
      <geometry>
        <cylinder length="0.08" radius="0.08"/>
      </geometry>
    </collision>
    <collision>
      <origin rpy="0 0 0" xyz="0 0 0.01"/>
      <geometry>
        <sphere radius="0.08"/>
      </geometry>
    </collision>
    <collision>
      <origin rpy="0 0 0" xyz="0 0 -0.07"/>
      <geometry>
        <sphere radius="0.08"/>
      </geometry>
    </collision>
  </link>
  <joint name="larm_joint6" type="revolute">
    <safety_controller k_position="100.0" k_velocity="40.0" soft_lower_limit="-0.0175" soft_upper_limit="3.7525"/>
    <origin rpy="1.57079632679 0 0" xyz="0 0 0"/>
    <parent link="larm_link5"/>
    <child link="larm_link6"/>
    <axis xyz="0 0 1"/>
    <limit effort="12" lower="-0.0175" upper="3.7525" velocity="2.6100"/>
  </joint>
  <link name="larm_link7">
    <visual>
      <geometry>
        <mesh filename="package://franka_description/meshes/visual/link7.dae"/>
      </geometry>
    </visual>
    <collision>
      <origin rpy="0 0 0" xyz="0 0 0.01"/>
      <geometry>
        <cylinder length="0.14" radius="0.07"/>
      </geometry>
    </collision>
    <collision>
      <origin rpy="0 0 0" xyz="0 0 0.08"/>
      <geometry>
        <sphere radius="0.07"/>
      </geometry>
    </collision>
    <collision>
      <origin rpy="0 0 0" xyz="0 0 -0.06"/>
      <geometry>
        <sphere radius="0.07"/>
      </geometry>
    </collision>
  </link>
  <joint name="larm_joint7" type="revolute">
    <safety_controller k_position="100.0" k_velocity="40.0" soft_lower_limit="-2.8973" soft_upper_limit="2.8973"/>
    <origin rpy="1.57079632679 0 0" xyz="0.088 0 0"/>
    <parent link="larm_link6"/>
    <child link="larm_link7"/>
    <axis xyz="0 0 1"/>
    <limit effort="12" lower="-2.8973" upper="2.8973" velocity="2.6100"/>
  </joint>
  <link name="larm_link8">
    <collision>
      <origin rpy="3.14159265359 1.57079632679 1.57079632679" xyz="0.0424 0.0424 -0.0250"/>
      <geometry>
        <cylinder length="0.01" radius="0.06"/>
      </geometry>
    </collision>
    <collision>
      <origin rpy="0 0 0" xyz="0.0424 0.0424 -0.02"/>
      <geometry>
        <sphere radius="0.06"/>
      </geometry>
    </collision>
    <collision>
      <origin rpy="0 0 0" xyz="0.0424 0.0424 -0.03"/>
      <geometry>
        <sphere radius="0.06"/>
      </geometry>
    </collision>
  </link>
  <joint name="larm_joint8" type="fixed">
    <origin rpy="0 0 0" xyz="0 0 0.107"/>
    <parent link="larm_link7"/>
    <child link="larm_link8"/>
  </joint>
  <joint name="larm_hand_joint" type="fixed">
    <parent link="larm_link8"/>
    <child link="larm_hand"/>
    <origin rpy="0 0 -0.785398163397" xyz="0 0 0"/>
  </joint>
  <link name="larm_hand">
    <visual>
      <geometry>
        <mesh filename="package://franka_description/meshes/visual/hand.dae"/>
      </geometry>
    </visual>
    <collision>
      <origin rpy="0 1.57079632679 1.57079632679" xyz="0 0 0.04"/>
      <geometry>
        <cylinder length="0.1" radius="0.07"/>
      </geometry>
    </collision>
    <collision>
      <origin rpy="0 0 0" xyz="0 -0.05 0.04"/>
      <geometry>
        <sphere radius="0.07"/>
      </geometry>
    </collision>
    <collision>
      <origin rpy="0 0 0" xyz="0 0.05 0.04"/>
      <geometry>
        <sphere radius="0.07"/>
      </geometry>
    </collision>
    <collision>
      <origin rpy="0 1.57079632679 1.57079632679" xyz="0 0 0.1"/>
      <geometry>
        <cylinder length="0.1" radius="0.05"/>
      </geometry>
    </collision>
    <collision>
      <origin rpy="0 0 0" xyz="0 -0.05 0.1"/>
      <geometry>
        <sphere radius="0.05"/>
      </geometry>
    </collision>
    <collision>
      <origin rpy="0 0 0" xyz="0 0.05 0.1"/>
      <geometry>
        <sphere radius="0.05"/>
      </geometry>
    </collision>
  </link>
  <link name="larm_leftfinger">
    <visual>
      <geometry>
        <mesh filename="package://franka_description/meshes/visual/finger.dae"/>
      </geometry>
    </visual>
  </link>
  <link name="larm_rightfinger">
    <visual>
      <origin rpy="0 0 3.14159265359" xyz="0 0 0"/>
      <geometry>
        <mesh filename="package://franka_description/meshes/visual/finger.dae"/>
      </geometry>
    </visual>
  </link>
  <joint name="larm_finger_joint1" type="prismatic">
    <parent link="larm_hand"/>
    <child link="larm_leftfinger"/>
    <origin rpy="0 0 0" xyz="0 0 0.0584"/>
    <axis xyz="0 1 0"/>
    <limit effort="20" lower="0.0" upper="0.04" velocity="0.2"/>
  </joint>
  <joint name="larm_finger_joint2" type="prismatic">
    <parent link="larm_hand"/>
    <child link="larm_rightfinger"/>
    <origin rpy="0 0 0" xyz="0 0 0.0584"/>
    <axis xyz="0 -1 0"/>
    <limit effort="20" lower="0.0" upper="0.04" velocity="0.2"/>
    <mimic joint="larm_finger_joint1"/>
  </joint>
  <link name="fixed_base"/>
  <link name="dual_arm_base">
    <!--
    <visual>
      <origin xyz="0 -0.4 0" rpy="1.5707963267949 0.0 0.0" />
      <geometry>
        <mesh filename="package://franka_description/meshes/dual_franka_base.dae" scale="0.001 0.001 0.001" />
      </geometry>
      <material name="misumi">
        <color rgba="0.75 0.75 0.75 1.0"/>
      </material>
    </visual>
    <collision>
      <origin xyz="0 -0.4 0" rpy="1.5707963267949 0.0 0.0" />
      <geometry>
        <mesh filename="package://franka_description/meshes/dual_franka_base.dae" scale="0.001 0.001 0.001" />
      </geometry>
    </collision>
    -->
    <visual>
      <origin xyz="0.3 0 0.71"/>
      <geometry>
        <box size="0.6 1.2 0.02"/>
      </geometry>
      <material name="table">
        <color rgba="0.7 0.6 0.5 1.0"/>
      </material>
    </visual>
    <collision>
      <origin xyz="0.3 0 0.71"/>
      <geometry>
        <box size="0.6 1.2 0.02"/>
      </geometry>
    </collision>
    <inertial>
      <mass value="1000"/>
      <origin rpy="0 0 0" xyz="0.0 0.0 0.2"/>
      <inertia ixx="10.0" ixy="0.0" ixz="0.0" iyy="10.0" iyz="0.0" izz="10.0"/>
    </inertial>
  </link>
  <joint name="base_to_fixed" type="fixed">
    <parent link="dual_arm_base"/>
    <child link="fixed_base"/>
    <origin rpy="0.0 0.0 0.0" xyz="-0.08 0.0 0.8"/>
  </joint>
  <!--link name="table_plane">
    <visual>
      <origin xyz="0.3 0 0.01" />
      <geometry>
        <box size="0.6 1.2 0.02" />
      </geometry>
      <material name="table">
        <color rgba="0.7 0.6 0.5 1.0"/>
      </material>
    </visual>
    <collision>
      <origin xyz="0.3 0 0.01" />
      <geometry>
        <box size="0.6 1.2 0.02" />
      </geometry>
    </collision>
  </link-->
  <link name="controller_plane0">
    <visual>
      <origin xyz="0.3 0 0.01"/>
      <geometry>
        <box size="0.6 0.8 0.02"/>
      </geometry>
      <material name="plane">
        <color rgba="0.6 0.6 0.6 1.0"/>
      </material>
    </visual>
  </link>
  <!--link name="controller_plane1">
    <visual>
      <origin xyz="0.3 0 0.01" />
      <geometry>
        <box size="0.6 0.8 0.02" />
      </geometry>
      <material  name="plane" />
    </visual>
  </link-->
  <!--joint name="base_to_table_plane" type="fixed">
    <parent link="dual_arm_base" />
    <child  link="table_plane" />
    <origin xyz="0.0 0.0 0.8" rpy="0.0 0.0 0.0" />
  </joint-->
  <joint name="base_to_c_plane0" type="fixed">
    <parent link="dual_arm_base"/>
    <child link="controller_plane0"/>
    <origin rpy="0.0 0.0 0.0" xyz="0.0 0.0 0.2"/>
  </joint>
  <!--joint name="base_to_c_plane1" type="fixed">
    <parent link="dual_arm_base" />
    <child  link="controller_plane1" />
    <origin xyz="0.0 0.0 0.5" rpy="0.0 0.0 0.0" />
  </joint-->
  <link name="controller0">
    <visual>
      <origin xyz="0.3 0 0.134"/>
      <geometry>
        <box size="0.475 0.423 0.268"/>
      </geometry>
      <material name="controller">
        <color rgba="0.5 0.5 0.6 1.0"/>
      </material>
    </visual>
  </link>
  <!--link name="controller1">
    <visual>
      <origin xyz="0.3 0 0.134" />
      <geometry>
        <box size="0.475 0.423 0.268" />
      </geometry>
      <material name="controller"/>
    </visual>
  </link-->
  <joint name="base_to_c0" type="fixed">
    <parent link="dual_arm_base"/>
    <child link="controller0"/>
    <origin rpy="0.0 0.0 0.0" xyz="0.0 0.0 0.22"/>
  </joint>
  <!--joint name="base_to_c1" type="fixed">
    <parent link="dual_arm_base" />
    <child  link="controller1" />
    <origin xyz="0.0 0.0 0.52" rpy="0.0 0.0 0.0" />
  </joint-->
  <!--link name="dual_arm_booth">
    <visual>
      <origin rpy="1.5707963267949 0.0 0.0" xyz="0 -0.75 0"/>
      <geometry>
        <mesh filename="package://franka_description/meshes/dual_franka_booth.stl"
              scale="0.001 0.001 0.001" />
      </geometry>
      <material name="misumi">
        <color rgba="0.75 0.75 0.75 1.0"/>
      </material>
    </visual>
    <collision>
      <origin rpy="1.5707963267949 0.0 0.0" xyz="0 -0.75 0"/>
      <geometry>
        <mesh filename="package://franka_description/meshes/dual_franka_booth.stl"
              scale="0.001 0.001 0.001" />
      </geometry>
    </collision>
    <inertial>
      <mass value="1000"/>
      <origin rpy="0 0 0" xyz="0.0 0.0 0.8"/>
      <inertia ixx="1.0" ixy="0.0" ixz="0.0" iyy="1.0" iyz="0.0" izz="1.0"/>
    </inertial>
  </link>
  <joint name="base_to_booth" type="fixed">
    <parent link="dual_arm_base"/>
    <child link="dual_arm_booth"/>
    <origin rpy="0.0 0.0 0.0" xyz="-0.11 0.0 0.0"/>
  </joint-->
  <link name="display">
    <visual>
      <geometry>
        <!--box size="0.03 0.817 0.342"/-->
        <!-- 34inch wide -->
        <box size="0.015 0.165 0.150"/>
        <!-- 12inch -->
      </geometry>
      <material name="Display">
        <color rgba="0.15 0.15 0.15 1.0"/>
      </material>
    </visual>
    <collision>
      <geometry>
        <!--box size="0.03 0.817 0.342"/-->
        <box size="0.015 0.165 0.150"/>
        <!-- 12inch -->
      </geometry>
    </collision>
  </link>
  <joint name="base_to_dispaly" type="fixed">
    <parent link="dual_arm_base"/>
    <child link="display"/>
    <origin rpy="0.0 0.2 0.0" xyz="0.0 0.0 1.66"/>
  </joint>
  <!-- test xtion frame -->
  <link name="camera_link"/>
  <joint name="camera_fixed_joint" type="fixed">
    <parent link="dual_arm_base"/>
    <child link="camera_link"/>
    <origin rpy="0 0.88 0" xyz="-0.22 -0.0 1.46"/>
  </joint>
  <!-- create camera frame-->
  <link name="fisheye_frame"/>
  <joint name="fisheye_fixed_joint" type="fixed">
    <parent link="dual_arm_base"/>
    <child link="fisheye_frame"/>
    <origin rpy="0 1.3 0" xyz="0.07 0 1.9"/>
  </joint>
  <!-- realsense -->
  <link name="rarm_camera_link">
    <!-- <geometry> -->
    <!--   <mesh filename="../../jsk_panda_accessories/realsense/realsense_with_mount.stl"/> -->
    <!-- </geometry> -->
    <inertial>
      <origin rpt="0 0 0" xyz="0.0 0.0 0.0"/>
      <mass value="0.005"/>
      <inertia ixx="0.0000000001" ixy="0.0000000001" ixz="0.0000000001" iyy="0.0000000001" iyz="0.0000000001" izz="0.0000000001"/>
    </inertial>
  </link>
  <joint name="rarm_camera_joint" type="fixed">
    <parent link="rarm_link7"/>
    <child link="rarm_camera_link"/>
    <origin rpy="1.57079632 -1.57079632 0.78539816" xyz="0.049497475 -0.02828421 0.12375"/>
  </joint>
  <link name="larm_camera_link">
    <!-- <geometry> -->
    <!--   <mesh filename="../../jsk_panda_accessories/realsense/realsense_with_mount.stl"/> -->
    <!-- </geometry> -->
    <inertial>
      <origin rpt="0 0 0" xyz="0.0 0.0 0.0"/>
      <mass value="0.005"/>
      <inertia ixx="0.0000000001" ixy="0.0000000001" ixz="0.0000000001" iyy="0.0000000001" iyz="0.0000000001" izz="0.0000000001"/>
    </inertial>
  </link>
  <joint name="larm_camera_joint" type="fixed">
    <parent link="larm_link7"/>
    <child link="larm_camera_link"/>
    <origin rpy="1.57079632 -1.57079632 0.78539816" xyz="0.049497475 -0.02828421 0.12375"/>
  </joint>
  <!-- eus end effector link -->
  <link name="rarm_end_effector">
  </link>
  <joint name="rarm_end_effector_joint" type="fixed">
    <parent link="rarm_link7"/>
    <child link="rarm_end_effector"/>
    <origin rpy="0 -1.570796327 -0.785398163" xyz="0 0 0.2"/>
  </joint>
  <link name="larm_end_effector">
  </link>
  <joint name="larm_end_effector_joint" type="fixed">
    <parent link="larm_link7"/>
    <child link="larm_end_effector"/>
    <origin rpy="0 -1.570796327 -0.785398163" xyz="0 0 0.2"/>
  </joint>
  <transmission name="right_joint1_trans">
    <type>transmission_interface/SimpleTransmission</type>
    <joint name="right_joint1">
      <hardwareInterface>hardware_interface/VelocityJointInterface</hardwareInterface>
    </joint>
    <actuator name="right_joint1_motor">
      <hardwareInterface>hardware_interface/VelocityJointInterface</hardwareInterface>
      <mechanicalReduction>1</mechanicalReduction>
    </actuator>
  </transmission>
  <transmission name="right_joint2_trans">
    <type>transmission_interface/SimpleTransmission</type>
    <joint name="right_joint2">
      <hardwareInterface>hardware_interface/VelocityJointInterface</hardwareInterface>
    </joint>
    <actuator name="right_joint2_motor">
      <hardwareInterface>hardware_interface/VelocityJointInterface</hardwareInterface>
      <mechanicalReduction>1</mechanicalReduction>
    </actuator>
  </transmission>
  <transmission name="right_joint3_trans">
    <type>transmission_interface/SimpleTransmission</type>
    <joint name="right_joint3">
      <hardwareInterface>hardware_interface/VelocityJointInterface</hardwareInterface>
    </joint>
    <actuator name="right_joint3_motor">
      <hardwareInterface>hardware_interface/VelocityJointInterface</hardwareInterface>
      <mechanicalReduction>1</mechanicalReduction>
    </actuator>
  </transmission>
  <transmission name="right_joint4_trans">
    <type>transmission_interface/SimpleTransmission</type>
    <joint name="right_joint4">
      <hardwareInterface>hardware_interface/VelocityJointInterface</hardwareInterface>
    </joint>
    <actuator name="right_joint4_motor">
      <hardwareInterface>hardware_interface/VelocityJointInterface</hardwareInterface>
      <mechanicalReduction>1</mechanicalReduction>
    </actuator>
  </transmission>
  <transmission name="right_joint5_trans">
    <type>transmission_interface/SimpleTransmission</type>
    <joint name="right_joint5">
      <hardwareInterface>hardware_interface/VelocityJointInterface</hardwareInterface>
    </joint>
    <actuator name="right_joint5_motor">
      <hardwareInterface>hardware_interface/VelocityJointInterface</hardwareInterface>
      <mechanicalReduction>1</mechanicalReduction>
    </actuator>
  </transmission>
  <transmission name="right_joint6_trans">
    <type>transmission_interface/SimpleTransmission</type>
    <joint name="right_joint6">
      <hardwareInterface>hardware_interface/VelocityJointInterface</hardwareInterface>
    </joint>
    <actuator name="right_joint6_motor">
      <hardwareInterface>hardware_interface/VelocityJointInterface</hardwareInterface>
      <mechanicalReduction>1</mechanicalReduction>
    </actuator>
  </transmission>
  <transmission name="right_joint7_trans">
    <type>transmission_interface/SimpleTransmission</type>
    <joint name="right_joint7">
      <hardwareInterface>hardware_interface/VelocityJointInterface</hardwareInterface>
    </joint>
    <actuator name="right_joint7_motor">
      <hardwareInterface>hardware_interface/VelocityJointInterface</hardwareInterface>
      <mechanicalReduction>1</mechanicalReduction>
    </actuator>
  </transmission>
  <transmission name="left_joint1_trans">
    <type>transmission_interface/SimpleTransmission</type>
    <joint name="left_joint1">
      <hardwareInterface>hardware_interface/VelocityJointInterface</hardwareInterface>
    </joint>
    <actuator name="left_joint1_motor">
      <hardwareInterface>hardware_interface/VelocityJointInterface</hardwareInterface>
      <mechanicalReduction>1</mechanicalReduction>
    </actuator>
  </transmission>
  <transmission name="left_joint2_trans">
    <type>transmission_interface/SimpleTransmission</type>
    <joint name="left_joint2">
      <hardwareInterface>hardware_interface/VelocityJointInterface</hardwareInterface>
    </joint>
    <actuator name="left_joint2_motor">
      <hardwareInterface>hardware_interface/VelocityJointInterface</hardwareInterface>
      <mechanicalReduction>1</mechanicalReduction>
    </actuator>
  </transmission>
  <transmission name="left_joint3_trans">
    <type>transmission_interface/SimpleTransmission</type>
    <joint name="left_joint3">
      <hardwareInterface>hardware_interface/VelocityJointInterface</hardwareInterface>
    </joint>
    <actuator name="left_joint3_motor">
      <hardwareInterface>hardware_interface/VelocityJointInterface</hardwareInterface>
      <mechanicalReduction>1</mechanicalReduction>
    </actuator>
  </transmission>
  <transmission name="left_joint4_trans">
    <type>transmission_interface/SimpleTransmission</type>
    <joint name="left_joint4">
      <hardwareInterface>hardware_interface/VelocityJointInterface</hardwareInterface>
    </joint>
    <actuator name="left_joint4_motor">
      <hardwareInterface>hardware_interface/VelocityJointInterface</hardwareInterface>
      <mechanicalReduction>1</mechanicalReduction>
    </actuator>
  </transmission>
  <transmission name="left_joint5_trans">
    <type>transmission_interface/SimpleTransmission</type>
    <joint name="left_joint5">
      <hardwareInterface>hardware_interface/VelocityJointInterface</hardwareInterface>
    </joint>
    <actuator name="left_joint5_motor">
      <hardwareInterface>hardware_interface/VelocityJointInterface</hardwareInterface>
      <mechanicalReduction>1</mechanicalReduction>
    </actuator>
  </transmission>
  <transmission name="left_joint6_trans">
    <type>transmission_interface/SimpleTransmission</type>
    <joint name="left_joint6">
      <hardwareInterface>hardware_interface/VelocityJointInterface</hardwareInterface>
    </joint>
    <actuator name="left_joint6_motor">
      <hardwareInterface>hardware_interface/VelocityJointInterface</hardwareInterface>
      <mechanicalReduction>1</mechanicalReduction>
    </actuator>
  </transmission>
  <transmission name="left_joint7_trans">
    <type>transmission_interface/SimpleTransmission</type>
    <joint name="left_joint7">
      <hardwareInterface>hardware_interface/VelocityJointInterface</hardwareInterface>
    </joint>
    <actuator name="left_joint7_motor">
      <hardwareInterface>hardware_interface/VelocityJointInterface</hardwareInterface>
      <mechanicalReduction>1</mechanicalReduction>
    </actuator>
  </transmission>
  <transmission name="right_finger_joint1_trans">
    <type>transmission_interface/SimpleTransmission</type>
    <joint name="right_finger_joint1">
      <hardwareInterface>hardware_interface/VelocityJointInterface</hardwareInterface>
    </joint>
    <actuator name="right_finger_joint1_motor">
      <hardwareInterface>hardware_interface/VelocityJointInterface</hardwareInterface>
      <mechanicalReduction>1</mechanicalReduction>
    </actuator>
  </transmission>
  <transmission name="right_finger_joint2_trans">
    <type>transmission_interface/SimpleTransmission</type>
    <joint name="right_finger_joint2">
      <hardwareInterface>hardware_interface/VelocityJointInterface</hardwareInterface>
    </joint>
    <actuator name="right_finger_joint2_motor">
      <hardwareInterface>hardware_interface/VelocityJointInterface</hardwareInterface>
      <mechanicalReduction>1</mechanicalReduction>
    </actuator>
  </transmission>
  <transmission name="left_finger_joint1_trans">
    <type>transmission_interface/SimpleTransmission</type>
    <joint name="left_finger_joint1">
      <hardwareInterface>hardware_interface/VelocityJointInterface</hardwareInterface>
    </joint>
    <actuator name="left_finger_joint1_motor">
      <hardwareInterface>hardware_interface/VelocityJointInterface</hardwareInterface>
      <mechanicalReduction>1</mechanicalReduction>
    </actuator>
  </transmission>
  <transmission name="left_finger_joint2_trans">
    <type>transmission_interface/SimpleTransmission</type>
    <joint name="left_finger_joint2">
      <hardwareInterface>hardware_interface/VelocityJointInterface</hardwareInterface>
    </joint>
    <actuator name="left_finger_joint2_motor">
      <hardwareInterface>hardware_interface/VelocityJointInterface</hardwareInterface>
      <mechanicalReduction>1</mechanicalReduction>
    </actuator>
  </transmission>
  <!-- camera -->
  <gazebo reference="fisheye_frame">
    <sensor name="fisheye_camera_sensor" type="wideanglecamera">
      <!--pose>${pose}</pose-->
      <always_on>true</always_on>
      <update_rate>15</update_rate>
      <visualize>false</visualize>
      <camera name="fisheye_camera">
        <horizontal_fov>3.14</horizontal_fov>
        <image>
          <width>2048</width>
          <height>2048</height>
          <format>R8G8B8</format>
        </image>
        <clip>
          <near>0.02</near>
          <far>300</far>
        </clip>
        <lens>
          <!-- for Fisheye -->
          <!-- type: gnomonical, stereographic, equidistant, equisolid_angle, orthographic, custom -->
          <!-- More information here: https://en.wikipedia.org/wiki/Fisheye_lens#Mapping_function -->
          <!--type>equidistant</type-->
          <type>custom</type>
          <!-- manually defined mapping function r = c1*f*fun(theta/c2 + c3) -->
          <custom_function>
            <c1>2</c1>
            <c2>2</c2>
            <c3>0</c3>
            <f>0.63661977</f>
            <!-- ( 2.0 / pi ) -->
            <fun>id</fun>
            <!-- one of sin,tan,id -->
          </custom_function>
          <!-- if it is set to `true` your horizontal FOV will ramain as defined -->
          <!-- othervise it depends on lens type and custom function, if there is one -->
          <scale_to_hfov>false</scale_to_hfov>
          <cutoff_angle>1.5707</cutoff_angle>
          <!-- clip everything that is outside of this angle -->
          <!-- resolution of the cubemap texture, the highter it is - the sharper is your image -->
          <env_texture_size>2048</env_texture_size>
        </lens>
      </camera>
      <plugin filename="libgazebo_ros_camera.so" name="camera_controller">
        <alwaysOn>true</alwaysOn>
        <updateRate>0.0</updateRate>
        <!-- ? -->
        <cameraName>fisheye_camera</cameraName>
        <imageTopicName>image_raw</imageTopicName>
        <cameraInfoTopicName>camera_info</cameraInfoTopicName>
        <frameName>fisheye_frame</frameName>
        <hackBaseline>0.07</hackBaseline>
        <distortionK1>0.0</distortionK1>
        <distortionK2>0.0</distortionK2>
        <distortionK3>0.0</distortionK3>
        <distortionT1>0.0</distortionT1>
        <distortionT2>0.0</distortionT2>
      </plugin>
    </sensor>
  </gazebo>
  <gazebo>
    <plugin filename="libgazebo_ros_control.so" name="gazebo_ros_control">
      <!--robotNamespace>/</robotNamespace-->
      <legacyModeNS>false</legacyModeNS>
      <robotSimType>gazebo_ros_control/DefaultRobotHWSim</robotSimType>
    </plugin>
  </gazebo>
</robot>

